Workbook

Sheet Read Me
A1: Bluom — Apple Search Ads Campaign Drafts
A2: USA / UK / Canada — built from Bluom's exported Apple Search Ads popularity data + the Master SEO Keywords sheet
A4: What this is
A5: A draft Apple Search Ads (Advanced) campaign structure for Bluom, one campaign per country (USA, UK, Canada tabs), built from the 102 keywords you exported from Apple's own Search Ads popularity tool. Ad groups mirror Bluom's real site navigation (Fuel / Move / Plans / Wellness / Women / Tools) plus a Fasting & Metabolic group and an AI Coach & Scanner group for your core differentiator, so messaging stays consistent with your site and blog.
A7: How to use it
A8: 1. Review each country tab. Ad Group and Keyword columns are fixed to Apple's actual popularity scores — Match Type, Tier, and Suggested Max CPT are starting recommendations, not final bids.
A9: 2. Yellow cells on the 'Bid Tiers' tab are the only cells meant to be edited — change the CPT ranges there and every country tab recalculates automatically (they're formulas, not typed-in numbers).
A10: 3. Build the campaigns in Apple Search Ads Campaign Manager by hand — Apple does not support bulk CSV import for Advanced campaigns, so this workbook is the build sheet you work from, not an upload file.
A11: 4. Start every ad group's keywords at the low end of its Suggested Max CPT range, let it run ~1-2 weeks, then adjust using Apple's own 'Recommended bid' shown in Campaign Manager and your real CPA/CPT data.
A13: Important caveats — read before you bid
A14: Suggested Max CPT ranges are ESTIMATES based on typical Health & Fitness category CPTs, not data pulled from Apple. Apple Search Ads bidding is a real-time auction — actual winning bids depend on competition at the moment you run the campaign. Use these as a starting point only; Campaign Manager will show you Apple's own 'Recommended bid range' once the ad group is live, and that should win over this sheet.
A15: 'Popularity Score' is Apple's own 0-100 relative search-popularity metric (not a raw search volume number). A score of '5' in your source files is Apple's own '<5' floor value — meaning negligible but not necessarily zero. Blank cells mean Apple returned no data at all for that term in that market.
... A21: Ad group theming cross-checked against: Master SEO Keywords Google Sheet and Bluom's live site navigation (Fuel/Move/Plans/Wellness/Women/Tools).

Sheet Campaign Plan
A1: Campaign Plan — structure to build in Apple Search Ads Campaign Manager
A3: One Advanced campaign per country (USA, UK, Canada), each containing these ad groups:
A5: Ad Group | B5: Purpose | C5: Search Match | D5: Notes
A6: Brand | B6: Protects 'bluom' / 'bluom app' / 'bluom health os' from competitors bidding on your own name. | C6: Off | D6: Not in your keyword export — add manually. Bid low ($0.25–$0.50); no real competition expected on your own name.
A7: Discovery | B7: Search Match ON, zero explicit keywords — lets Apple's algorithm surface new relevant search terms you haven't thought of. | C7: On | D7: Review its Search Term Report weekly; promote any strong performer into the matching Exact Match ad group below, then add it as a negative here so spend doesn't split.
A8: AI Coach & Scanner | B8: Bluom's core differentiator — AI photo/food scanning and AI coaching. | C8: Off | D8: Highest strategic priority even where popularity scores are low — this is what makes Bluom different from MyFitnessPal-style manual loggers.
A9: Fuel (Nutrition) | B9: Food, diet, macro, meal & recipe tracking. | C9: Off | D9: Largest ad group by keyword count. Watch for cannibalization between 'macro' / 'macros' / 'macro tracker' etc.
A10: Move (Fitness) | B10: Workouts, gym, running, cycling, steps. | C10: Off | D10: Broad category — high competition on head terms like 'workout' and 'gym'.
A11: Plans (Habits) | B11: Habit building, motivation, planning. | C11: Off | D11: 'tracker' alone lives here and is very generic — consider dropping or tight negatives.
A12: Wellness (Mind & Sleep) | B12: Sleep, meditation, brain training, hydration. | C12: Off | D12: 'health' is a broad head term here — cap budget and monitor CPA.
A13: Women's Health | B13: Period, cycle, ovulation, PCOS. | C13: Off | D13: High-relevance, underserved category in most fitness-app advertising — good differentiation opportunity.
A14: Fasting & Metabolic | B14: Fasting, keto, glucose, insulin. | C14: Off | D14: Matches your Fasting blog content pillar — keep ad copy and landing consistent with that content.
A15: Tools (Calculators) | B15: BMI and nutrition calculators. | C15: Off | D15: Smallest group; low volume across all three markets but cheap and high-intent.
A17: Not included (flag for Jorge):
A18: • Competitor campaign (MyFitnessPal, Lose It, Noom, Zero, Fitbit, etc.) — deliberate call, tell me if you want it drafted.
A19: • Localized (non-English) ad groups for these three markets — your keyword export was English-only. The Master SEO Keywords sheet's 'ASO Clean + New Markets' tab has German/Dutch/French/etc. data if you want a Europe pass next.

Sheet Bid Tiers
A1: Bid Tiers — edit the yellow cells; every country tab recalculates automatically
A3: Tier | B3: Min Score | C3: Max Score | D3: Sugg. Min CPT ($) | E3: Sugg. Max CPT ($) | F3: Description
A4: Tier D — Below Threshold (<5) | B4: 0 | C4: 5 | D4: 0.3 | E4: 0.6 | F4: Apple's own '<5' floor value — negligible reported popularity, but cheap and low-competition. Good Discovery/testing candidates.
A5: Tier C — Long-Tail | B5: 6 | C5: 19 | D5: 0.5 | E5: 0.9 | F5: Real but low popularity. High relevance, low competition — often the best cost-per-install in the account.
A6: Tier B — Mid Volume | B6: 20 | C6: 44 | D6: 0.8 | E6: 1.5 | F6: Moderate competition. Solid steady-volume terms.
A7: Tier A — Head Term | B7: 45 | C7: 100 | D7: 1.5 | E7: 3 | F7: Highest popularity, highest competition. Cap budget and watch CPA closely.
A9: Yellow cells are the only inputs meant to be edited on this whole workbook.

Sheet USA
A1: Bluom — Apple Search Ads — USA
A2: Draft ad group / keyword / bid structure. Edit Match Type or Notes freely — Tier and Suggested Max CPT are formulas pulling from the 'Bid Tiers' tab.
A3: Ad Group | B3: Keyword | C3: Match Type | D3: Popularity Score | E3: Tier | F3: Suggested Max CPT ($) | G3: Notes
A4: Brand | B4: bluom | C4: Exact | D4: — | E4: Brand | F4: 0.4 | G4: Defensive brand term — no organic competition expected.
A5: Brand | B5: bluom app | C5: Exact | D5: — | E5: Brand | F5: 0.4 | G5: Defensive brand term.
A6: Brand | B6: bluom health os | C6: Exact | D6: — | E6: Brand | F6: 0.4 | G6: Defensive brand term — matches your new positioning line.
A7: Discovery | B7: [Search Match ON — no explicit keywords] | C7: Search Match | D7: — | E7: — | F7: 0.5 | G7: Let Apple surface new search terms; review weekly and graduate winners into the matching Exact Match group.
A8: AI Coach & Scanner | B8: ai fitness | C8: Exact | D8: 5 | E8: =IF(D8="","No Data",INDEX('Bid Tiers'!$A$4:$A$7,MATCH(D8,'Bid Tiers'!$B$4:$B$7,1))) -> Tier D — Below Threshold (<5) | F8: =IF(D8="",0.3,INDEX('Bid Tiers'!$E$4:$E$7,MATCH(D8,'Bid Tiers'!$B$4:$B$7,1))) -> 0.6
A9: AI Coach & Scanner | B9: AI Calorie | C9: Exact | D9: 5 | E9: =IF(D9="","No Data",INDEX('Bid Tiers'!$A$4:$A$7,MATCH(D9,'Bid Tiers'!$B$4:$B$7,1))) -> Tier D — Below Threshold (<5) | F9: =IF(D9="",0.3,INDEX('Bid Tiers'!$E$4:$E$7,MATCH(D9,'Bid Tiers'!$B$4:$B$7,1))) -> 0.6
A10: AI Coach & Scanner | B10: AI Calories | C10: Exact | D10: 5 | E10: =IF(D10="","No Data",INDEX('Bid Tiers'!$A$4:$A$7,MATCH(D10,'Bid Tiers'!$B$4:$B$7,1))) -> Tier D — Below Threshold (<5) | F10: =IF(D10="",0.3,INDEX('Bid Tiers'!$E$4:$E$7,MATCH(D10,'Bid Tiers'!$B$4:$B$7,1))) -> 0.6
A11: AI Coach & Scanner | B11: AI nutrition | C11: Exact | E11: =IF(D11="","No Data",INDEX('Bid Tiers'!$A$4:$A$7,MATCH(D11,'Bid Tiers'!$B$4:$B$7,1))) -> No Data | F11: =IF(D11="",0.3,INDEX('Bid Tiers'!$E$4:$E$7,MATCH(D11,'Bid Tiers'!$B$4:$B$7,1))) -> 0.3
A12: AI Coach & Scanner | B12: ai food | C12: Exact | E12: =IF(D12="","No Data",INDEX('Bid Tiers'!$A$4:$A$7,MATCH(D12,'Bid Tiers'!$B$4:$B$7,1))) -> No Data | F12: =IF(D12="",0.3,INDEX('Bid Tiers'!$E$4:$E$7,MATCH(D12,'Bid Tiers'!$B$4:$B$7,1))) -> 0.3
A13: AI Coach & Scanner | B13: meal scanner | C13: Exact | D13: 5 | E13: =IF(D13="","No Data",INDEX('Bid Tiers'!$A$4:$A$7,MATCH(D13,'Bid Tiers'!$B$4:$B$7,1))) -> Tier D — Below Threshold (<5) | F13: =IF(D13="",0.3,INDEX('Bid Tiers'!$E$4:$E$7,MATCH(D13,'Bid Tiers'!$B$4:$B$7,1))) -> 0.6
A14: AI Coach & Scanner | B14: ai coach | C14: Exact | D14: 5 | E14: =IF(D14="","No Data",INDEX('Bid Tiers'!$A$4:$A$7,MATCH(D14,'Bid Tiers'!$B$4:$B$7,1))) -> Tier D — Below Threshold (<5) | F14: =IF(D14="",0.3,INDEX('Bid Tiers'!$E$4:$E$7,MATCH(D14,'Bid Tiers'!$B$4:$B$7,1))) -> 0.6
A15: AI Coach & Scanner | B15: scanner | C15: Exact | D15: 61 | E15: =IF(D15="","No Data",INDEX('Bid Tiers'!$A$4:$A$7,MATCH(D15,'Bid Tiers'!$B$4:$B$7,1))) -> Tier A — Head Term | F15: =IF(D15="",0.3,INDEX('Bid Tiers'!$E$4:$E$7,MATCH(D15,'Bid Tiers'!$B$4:$B$7,1))) -> 3 | G15: Broad head term for the AI photo/food scanning feature — Bluom's core differentiator. Worth the higher bid.
A16: AI Coach & Scanner | B16: food scanner | C16: Exact | D16: 50 | E16: =IF(D16="","No Data",INDEX('Bid Tiers'!$A$4:$A$7,MATCH(D16,'Bid Tiers'!$B$4:$B$7,1))) -> Tier A — Head Term | F16: =IF(D16="",0.3,INDEX('Bid Tiers'!$E$4:$E$7,MATCH(D16,'Bid Tiers'!$B$4:$B$7,1))) -> 3
A17: AI Coach & Scanner | B17: photo calorie | C17: Exact | D17: 5 | E17: =IF(D17="","No Data",INDEX('Bid Tiers'!$A$4:$A$7,MATCH(D17,'Bid Tiers'!$B$4:$B$7,1))) -> Tier D — Below Threshold (<5) | F17: =IF(D17="",0.3,INDEX('Bid Tiers'!$E$4:$E$7,MATCH(D17,'Bid Tiers'!$B$4:$B$7,1))) -> 0.6
A18: AI Coach & Scanner | B18: nutrition scanner | C18: Exact | D18: 5 | E18: =IF(D18="","No Data",INDEX('Bid Tiers'!$A$4:$A$7,MATCH(D18,'Bid Tiers'!$B$4:$B$7,1))) -> Tier D — Below Threshold (<5) | F18: =IF(D18="",0.3,INDEX('Bid Tiers'!$E$4:$E$7,MATCH(D18,'Bid Tiers'!$B$4:$B$7,1))) -> 0.6
A19: Fuel (Nutrition) | B19: food | C19: Exact | D19: 65 | E19: =IF(D19="","No Data",INDEX('Bid Tiers'!$A$4:$A$7,MATCH(D19,'Bid Tiers'!$B$4:$B$7,1))) -> Tier A — Head Term | F19: =IF(D19="",0.3,INDEX('Bid Tiers'!$E$4:$E$7,MATCH(D19,'Bid Tiers'!$B$4:$B$7,1))) -> 3
A20: Fuel (Nutrition) | B20: diet | C20: Exact | D20: 5 | E20: =IF(D20="","No Data",INDEX('Bid Tiers'!$A$4:$A$7,MATCH(D20,'Bid Tiers'!$B$4:$B$7,1))) -> Tier D — Below Threshold (<5) | F20: =IF(D20="",0.3,INDEX('Bid Tiers'!$E$4:$E$7,MATCH(D20,'Bid Tiers'!$B$4:$B$7,1))) -> 0.6
A21: Fuel (Nutrition) | B21: weight | C21: Exact | D21: 5 | E21: =IF(D21="","No Data",INDEX('Bid Tiers'!$A$4:$A$7,MATCH(D21,'Bid Tiers'!$B$4:$B$7,1))) -> Tier D — Below Threshold (<5) | F21: =IF(D21="",0.3,INDEX('Bid Tiers'!$E$4:$E$7,MATCH(D21,'Bid Tiers'!$B$4:$B$7,1))) -> 0.6
A22: Fuel (Nutrition) | B22: protein | C22: Exact | D22: 5 | E22: =IF(D22="","No Data",INDEX('Bid Tiers'!$A$4:$A$7,MATCH(D22,'Bid Tiers'!$B$4:$B$7,1))) -> Tier D — Below Threshold (<5) | F22: =IF(D22="",0.3,INDEX('Bid Tiers'!$E$4:$E$7,MATCH(D22,'Bid Tiers'!$B$4:$B$7,1))) -> 0.6
A23: Fuel (Nutrition) | B23: eating | C23: Exact | D23: 5 | E23: =IF(D23="","No Data",INDEX('Bid Tiers'!$A$4:$A$7,MATCH(D23,'Bid Tiers'!$B$4:$B$7,1))) -> Tier D — Below Threshold (<5) | F23: =IF(D23="",0.3,INDEX('Bid Tiers'!$E$4:$E$7,MATCH(D23,'Bid Tiers'!$B$4:$B$7,1))) -> 0.6
A24: Fuel (Nutrition) | B24: macro | C24: Exact | D24: 49 | E24: =IF(D24="","No Data",INDEX('Bid Tiers'!$A$4:$A$7,MATCH(D24,'Bid Tiers'!$B$4:$B$7,1))) -> Tier A — Head Term | F24: =IF(D24="",0.3,INDEX('Bid Tiers'!$E$4:$E$7,MATCH(D24,'Bid Tiers'!$B$4:$B$7,1))) -> 3
A25: Fuel (Nutrition) | B25: macros | C25: Exact | D25: 47 | E25: =IF(D25="","No Data",INDEX('Bid Tiers'!$A$4:$A$7,MATCH(D25,'Bid Tiers'!$B$4:$B$7,1))) -> Tier A — Head Term | F25: =IF(D25="",0.3,INDEX('Bid Tiers'!$E$4:$E$7,MATCH(D25,'Bid Tiers'!$B$4:$B$7,1))) -> 3
A26: Fuel (Nutrition) | B26: macros tracker | C26: Exact | D26: 5 | E26: =IF(D26="","No Data",INDEX('Bid Tiers'!$A$4:$A$7,MATCH(D26,'Bid Tiers'!$B$4:$B$7,1))) -> Tier D — Below Threshold (<5) | F26: =IF(D26="",0.3,INDEX('Bid Tiers'!$E$4:$E$7,MATCH(D26,'Bid Tiers'!$B$4:$B$7,1))) -> 0.6
A27: Fuel (Nutrition) | B27: macro tracker | C27: Exact | D27: 54 | E27: =IF(D27="","No Data",INDEX('Bid Tiers'!$A$4:$A$7,MATCH(D27,'Bid Tiers'!$B$4:$B$7,1))) -> Tier A — Head Term | F27: =IF(D27="",0.3,INDEX('Bid Tiers'!$E$4:$E$7,MATCH(D27,'Bid Tiers'!$B$4:$B$7,1))) -> 3
... A29: Fuel (Nutrition) | B29: meal tracker free | C29: Exact | D29: 5 | E29: =IF(D29="","No Data",INDEX('Bid Tiers'!$A$4:$A$7,MATCH(D29,'Bid Tiers'!$B$4:$B$7,1))) -> Tier D — Below Threshold (<5) | F29: =IF(D29="",0.3,INDEX('Bid Tiers'!$E$4:$E$7,MATCH(D29,'Bid Tiers'!$B$4:$B$7,1))) -> 0.6
A30: Fuel (Nutrition) | B30: plan personalizado | C30: Exact | E30: =IF(D30="","No Data",INDEX('Bid Tiers'!$A$4:$A$7,MATCH(D30,'Bid Tiers'!$B$4:$B$7,1))) -> No Data | F30: =IF(D30="",0.3,INDEX('Bid Tiers'!$E$4:$E$7,MATCH(D30,'Bid Tiers'!$B$4:$B$7,1))) -> 0.3 | G30: Spanish-language query appearing in English-market data — likely Hispanic/bilingual searchers. Keep for USA; re-check relevance for UK/Canada before activating.
A31: Fuel (Nutrition) | B31: nutrition plan | C31: Exact | D31: 5 | E31: =IF(D31="","No Data",INDEX('Bid Tiers'!$A$4:$A$7,MATCH(D31,'Bid Tiers'!$B$4:$B$7,1))) -> Tier D — Below Threshold (<5) | F31: =IF(D31="",0.3,INDEX('Bid Tiers'!$E$4:$E$7,MATCH(D31,'Bid Tiers'!$B$4:$B$7,1))) -> 0.6
A32: Fuel (Nutrition) | B32: cooking | C32: Exact | D32: 61 | E32: =IF(D32="","No Data",INDEX('Bid Tiers'!$A$4:$A$7,MATCH(D32,'Bid Tiers'!$B$4:$B$7,1))) -> Tier A — Head Term | F32: =IF(D32="",0.3,INDEX('Bid Tiers'!$E$4:$E$7,MATCH(D32,'Bid Tiers'!$B$4:$B$7,1))) -> 3
A33: Fuel (Nutrition) | B33: recipes | C33: Exact | D33: 5 | E33: =IF(D33="","No Data",INDEX('Bid Tiers'!$A$4:$A$7,MATCH(D33,'Bid Tiers'!$B$4:$B$7,1))) -> Tier D — Below Threshold (<5) | F33: =IF(D33="",0.3,INDEX('Bid Tiers'!$E$4:$E$7,MATCH(D33,'Bid Tiers'!$B$4:$B$7,1))) -> 0.6
A34: Fuel (Nutrition) | B34: meals | C34: Exact | D34: 5 | E34: =IF(D34="","No Data",INDEX('Bid Tiers'!$A$4:$A$7,MATCH(D34,'Bid Tiers'!$B$4:$B$7,1))) -> Tier D — Below Threshold (<5) | F34: =IF(D34="",0.3,INDEX('Bid Tiers'!$E$4:$E$7,MATCH(D34,'Bid Tiers'!$B$4:$B$7,1))) -> 0.6
A35: Fuel (Nutrition) | B35: cook | C35: Exact | D35: 50 | E35: =IF(D35="","No Data",INDEX('Bid Tiers'!$A$4:$A$7,MATCH(D35,'Bid Tiers'!$B$4:$B$7,1))) -> Tier A — Head Term | F35: =IF(D35="",0.3,INDEX('Bid Tiers'!$E$4:$E$7,MATCH(D35,'Bid Tiers'!$B$4:$B$7,1))) -> 3
A36: Fuel (Nutrition) | B36: dinner | C36: Exact | D36: 5 | E36: =IF(D36="","No Data",INDEX('Bid Tiers'!$A$4:$A$7,MATCH(D36,'Bid Tiers'!$B$4:$B$7,1))) -> Tier D — Below Threshold (<5) | F36: =IF(D36="",0.3,INDEX('Bid Tiers'!$E$4:$E$7,MATCH(D36,'Bid Tiers'!$B$4:$B$7,1))) -> 0.6
A37: Fuel (Nutrition) | B37: breakfast | C37: Exact | D37: 5 | E37: =IF(D37="","No Data",INDEX('Bid Tiers'!$A$4:$A$7,MATCH(D37,'Bid Tiers'!$B$4:$B$7,1))) -> Tier D — Below Threshold (<5) | F37: =IF(D37="",0.3,INDEX('Bid Tiers'!$E$4:$E$7,MATCH(D37,'Bid Tiers'!$B$4:$B$7,1))) -> 0.6
A38: Fuel (Nutrition) | B38: lunch | C38: Exact | D38: 5 | E38: =IF(D38="","No Data",INDEX('Bid Tiers'!$A$4:$A$7,MATCH(D38,'Bid Tiers'!$B$4:$B$7,1))) -> Tier D — Below Threshold (<5) | F38: =IF(D38="",0.3,INDEX('Bid Tiers'!$E$4:$E$7,MATCH(D38,'Bid Tiers'!$B$4:$B$7,1))) -> 0.6
A39: Fuel (Nutrition) | B39: prep | C39: Exact | D39: 5 | E39: =IF(D39="","No Data",INDEX('Bid Tiers'!$A$4:$A$7,MATCH(D39,'Bid Tiers'!$B$4:$B$7,1))) -> Tier D — Below Threshold (<5) | F39: =IF(D39="",0.3,INDEX('Bid Tiers'!$E$4:$E$7,MATCH(D39,'Bid Tiers'!$B$4:$B$7,1))) -> 0.6
A40: Fuel (Nutrition) | B40: carb counter | C40: Exact | D40: 5 | E40: =IF(D40="","No Data",INDEX('Bid Tiers'!$A$4:$A$7,MATCH(D40,'Bid Tiers'!$B$4:$B$7,1))) -> Tier D — Below Threshold (<5) | F40: =IF(D40="",0.3,INDEX('Bid Tiers'!$E$4:$E$7,MATCH(D40,'Bid Tiers'!$B$4:$B$7,1))) -> 0.6
A41: Fuel (Nutrition) | B41: meal prep | C41: Exact | D41: 5 | E41: =IF(D41="","No Data",INDEX('Bid Tiers'!$A$4:$A$7,MATCH(D41,'Bid Tiers'!$B$4:$B$7,1))) -> Tier D — Below Threshold (<5) | F41: =IF(D41="",0.3,INDEX('Bid Tiers'!$E$4:$E$7,MATCH(D41,'Bid Tiers'!$B$4:$B$7,1))) -> 0.6
...

Sheet UK
A1: Bluom — Apple Search Ads — UK
A2: Draft ad group / keyword / bid structure. Edit Match Type or Notes freely — Tier and Suggested Max CPT are formulas pulling from the 'Bid Tiers' tab.
A3: Ad Group | B3: Keyword | C3: Match Type | D3: Popularity Score | E3: Tier | F3: Suggested Max CPT ($) | G3: Notes
A4: Brand | B4: bluom | C4: Exact | D4: — | E4: Brand | F4: 0.4 | G4: Defensive brand term — no organic competition expected.
A5: Brand | B5: bluom app | C5: Exact | D5: — | E5: Brand | F5: 0.4 | G5: Defensive brand term.
A6: Brand | B6: bluom health os | C6: Exact | D6: — | E6: Brand | F6: 0.4 | G6: Defensive brand term — matches your new positioning line.
A7: Discovery | B7: [Search Match ON — no explicit keywords] | C7: Search Match | D7: — | E7: — | F7: 0.5 | G7: Let Apple surface new search terms; review weekly and graduate winners into the matching Exact Match group.
A8: AI Coach & Scanner | B8: ai fitness | C8: Exact | D8: 5 | E8: =IF(D8="","No Data",INDEX('Bid Tiers'!$A$4:$A$7,MATCH(D8,'Bid Tiers'!$B$4:$B$7,1))) -> Tier D — Below Threshold (<5) | F8: =IF(D8="",0.3,INDEX('Bid Tiers'!$E$4:$E$7,MATCH(D8,'Bid Tiers'!$B$4:$B$7,1))) -> 0.6
A9: AI Coach & Scanner | B9: AI Calorie | C9: Exact | E9: =IF(D9="","No Data",INDEX('Bid Tiers'!$A$4:$A$7,MATCH(D9,'Bid Tiers'!$B$4:$B$7,1))) -> No Data | F9: =IF(D9="",0.3,INDEX('Bid Tiers'!$E$4:$E$7,MATCH(D9,'Bid Tiers'!$B$4:$B$7,1))) -> 0.3
A10: AI Coach & Scanner | B10: AI Calories | C10: Exact | E10: =IF(D10="","No Data",INDEX('Bid Tiers'!$A$4:$A$7,MATCH(D10,'Bid Tiers'!$B$4:$B$7,1))) -> No Data | F10: =IF(D10="",0.3,INDEX('Bid Tiers'!$E$4:$E$7,MATCH(D10,'Bid Tiers'!$B$4:$B$7,1))) -> 0.3
A11: AI Coach & Scanner | B11: AI nutrition | C11: Exact | D11: 5 | E11: =IF(D11="","No Data",INDEX('Bid Tiers'!$A$4:$A$7,MATCH(D11,'Bid Tiers'!$B$4:$B$7,1))) -> Tier D — Below Threshold (<5) | F11: =IF(D11="",0.3,INDEX('Bid Tiers'!$E$4:$E$7,MATCH(D11,'Bid Tiers'!$B$4:$B$7,1))) -> 0.6
A12: AI Coach & Scanner | B12: ai food | C12: Exact | D12: 5 | E12: =IF(D12="","No Data",INDEX('Bid Tiers'!$A$4:$A$7,MATCH(D12,'Bid Tiers'!$B$4:$B$7,1))) -> Tier D — Below Threshold (<5) | F12: =IF(D12="",0.3,INDEX('Bid Tiers'!$E$4:$E$7,MATCH(D12,'Bid Tiers'!$B$4:$B$7,1))) -> 0.6
A13: AI Coach & Scanner | B13: meal scanner | C13: Exact | E13: =IF(D13="","No Data",INDEX('Bid Tiers'!$A$4:$A$7,MATCH(D13,'Bid Tiers'!$B$4:$B$7,1))) -> No Data | F13: =IF(D13="",0.3,INDEX('Bid Tiers'!$E$4:$E$7,MATCH(D13,'Bid Tiers'!$B$4:$B$7,1))) -> 0.3
A14: AI Coach & Scanner | B14: ai coach | C14: Exact | D14: 5 | E14: =IF(D14="","No Data",INDEX('Bid Tiers'!$A$4:$A$7,MATCH(D14,'Bid Tiers'!$B$4:$B$7,1))) -> Tier D — Below Threshold (<5) | F14: =IF(D14="",0.3,INDEX('Bid Tiers'!$E$4:$E$7,MATCH(D14,'Bid Tiers'!$B$4:$B$7,1))) -> 0.6
A15: AI Coach & Scanner | B15: scanner | C15: Exact | D15: 52 | E15: =IF(D15="","No Data",INDEX('Bid Tiers'!$A$4:$A$7,MATCH(D15,'Bid Tiers'!$B$4:$B$7,1))) -> Tier A — Head Term | F15: =IF(D15="",0.3,INDEX('Bid Tiers'!$E$4:$E$7,MATCH(D15,'Bid Tiers'!$B$4:$B$7,1))) -> 3 | G15: Broad head term for the AI photo/food scanning feature — Bluom's core differentiator. Worth the higher bid.
A16: AI Coach & Scanner | B16: food scanner | C16: Exact | D16: 49 | E16: =IF(D16="","No Data",INDEX('Bid Tiers'!$A$4:$A$7,MATCH(D16,'Bid Tiers'!$B$4:$B$7,1))) -> Tier A — Head Term | F16: =IF(D16="",0.3,INDEX('Bid Tiers'!$E$4:$E$7,MATCH(D16,'Bid Tiers'!$B$4:$B$7,1))) -> 3
A17: AI Coach & Scanner | B17: photo calorie | C17: Exact | E17: =IF(D17="","No Data",INDEX('Bid Tiers'!$A$4:$A$7,MATCH(D17,'Bid Tiers'!$B$4:$B$7,1))) -> No Data | F17: =IF(D17="",0.3,INDEX('Bid Tiers'!$E$4:$E$7,MATCH(D17,'Bid Tiers'!$B$4:$B$7,1))) -> 0.3
A18: AI Coach & Scanner | B18: nutrition scanner | C18: Exact | D18: 5 | E18: =IF(D18="","No Data",INDEX('Bid Tiers'!$A$4:$A$7,MATCH(D18,'Bid Tiers'!$B$4:$B$7,1))) -> Tier D — Below Threshold (<5) | F18: =IF(D18="",0.3,INDEX('Bid Tiers'!$E$4:$E$7,MATCH(D18,'Bid Tiers'!$B$4:$B$7,1))) -> 0.6
A19: Fuel (Nutrition) | B19: food | C19: Exact | D19: 58 | E19: =IF(D19="","No Data",INDEX('Bid Tiers'!$A$4:$A$7,MATCH(D19,'Bid Tiers'!$B$4:$B$7,1))) -> Tier A — Head Term | F19: =IF(D19="",0.3,INDEX('Bid Tiers'!$E$4:$E$7,MATCH(D19,'Bid Tiers'!$B$4:$B$7,1))) -> 3
A20: Fuel (Nutrition) | B20: diet | C20: Exact | D20: 5 | E20: =IF(D20="","No Data",INDEX('Bid Tiers'!$A$4:$A$7,MATCH(D20,'Bid Tiers'!$B$4:$B$7,1))) -> Tier D — Below Threshold (<5) | F20: =IF(D20="",0.3,INDEX('Bid Tiers'!$E$4:$E$7,MATCH(D20,'Bid Tiers'!$B$4:$B$7,1))) -> 0.6
A21: Fuel (Nutrition) | B21: weight | C21: Exact | D21: 5 | E21: =IF(D21="","No Data",INDEX('Bid Tiers'!$A$4:$A$7,MATCH(D21,'Bid Tiers'!$B$4:$B$7,1))) -> Tier D — Below Threshold (<5) | F21: =IF(D21="",0.3,INDEX('Bid Tiers'!$E$4:$E$7,MATCH(D21,'Bid Tiers'!$B$4:$B$7,1))) -> 0.6
A22: Fuel (Nutrition) | B22: protein | C22: Exact | D22: 5 | E22: =IF(D22="","No Data",INDEX('Bid Tiers'!$A$4:$A$7,MATCH(D22,'Bid Tiers'!$B$4:$B$7,1))) -> Tier D — Below Threshold (<5) | F22: =IF(D22="",0.3,INDEX('Bid Tiers'!$E$4:$E$7,MATCH(D22,'Bid Tiers'!$B$4:$B$7,1))) -> 0.6
A23: Fuel (Nutrition) | B23: eating | C23: Exact | D23: 5 | E23: =IF(D23="","No Data",INDEX('Bid Tiers'!$A$4:$A$7,MATCH(D23,'Bid Tiers'!$B$4:$B$7,1))) -> Tier D — Below Threshold (<5) | F23: =IF(D23="",0.3,INDEX('Bid Tiers'!$E$4:$E$7,MATCH(D23,'Bid Tiers'!$B$4:$B$7,1))) -> 0.6
A24: Fuel (Nutrition) | B24: macro | C24: Exact | D24: 41 | E24: =IF(D24="","No Data",INDEX('Bid Tiers'!$A$4:$A$7,MATCH(D24,'Bid Tiers'!$B$4:$B$7,1))) -> Tier B — Mid Volume | F24: =IF(D24="",0.3,INDEX('Bid Tiers'!$E$4:$E$7,MATCH(D24,'Bid Tiers'!$B$4:$B$7,1))) -> 1.5
A25: Fuel (Nutrition) | B25: macros | C25: Exact | D25: 38 | E25: =IF(D25="","No Data",INDEX('Bid Tiers'!$A$4:$A$7,MATCH(D25,'Bid Tiers'!$B$4:$B$7,1))) -> Tier B — Mid Volume | F25: =IF(D25="",0.3,INDEX('Bid Tiers'!$E$4:$E$7,MATCH(D25,'Bid Tiers'!$B$4:$B$7,1))) -> 1.5
A26: Fuel (Nutrition) | B26: macros tracker | C26: Exact | D26: 5 | E26: =IF(D26="","No Data",INDEX('Bid Tiers'!$A$4:$A$7,MATCH(D26,'Bid Tiers'!$B$4:$B$7,1))) -> Tier D — Below Threshold (<5) | F26: =IF(D26="",0.3,INDEX('Bid Tiers'!$E$4:$E$7,MATCH(D26,'Bid Tiers'!$B$4:$B$7,1))) -> 0.6
A27: Fuel (Nutrition) | B27: macro tracker | C27: Exact | D27: 43 | E27: =IF(D27="","No Data",INDEX('Bid Tiers'!$A$4:$A$7,MATCH(D27,'Bid Tiers'!$B$4:$B$7,1))) -> Tier B — Mid Volume | F27: =IF(D27="",0.3,INDEX('Bid Tiers'!$E$4:$E$7,MATCH(D27,'Bid Tiers'!$B$4:$B$7,1))) -> 1.5
A28: Fuel (Nutrition) | B28: meal tracker | C28: Exact | D28: 5 | E28: =IF(D28="","No Data",INDEX('Bid Tiers'!$A$4:$A$7,MATCH(D28,'Bid Tiers'!$B$4:$B$7,1))) -> Tier D — Below Threshold (<5) | F28: =IF(D28="",0.3,INDEX('Bid Tiers'!$E$4:$E$7,MATCH(D28,'Bid Tiers'!$B$4:$B$7,1))) -> 0.6
A29: Fuel (Nutrition) | B29: meal tracker free | C29: Exact | D29: 5 | E29: =IF(D29="","No Data",INDEX('Bid Tiers'!$A$4:$A$7,MATCH(D29,'Bid Tiers'!$B$4:$B$7,1))) -> Tier D — Below Threshold (<5) | F29: =IF(D29="",0.3,INDEX('Bid Tiers'!$E$4:$E$7,MATCH(D29,'Bid Tiers'!$B$4:$B$7,1))) -> 0.6
A30: Fuel (Nutrition) | B30: plan personalizado | C30: Exact | E30: =IF(D30="","No Data",INDEX('Bid Tiers'!$A$4:$A$7,MATCH(D30,'Bid Tiers'!$B$4:$B$7,1))) -> No Data | F30: =IF(D30="",0.3,INDEX('Bid Tiers'!$E$4:$E$7,MATCH(D30,'Bid Tiers'!$B$4:$B$7,1))) -> 0.3 | G30: Spanish-language query appearing in English-market data — likely Hispanic/bilingual searchers. Keep for USA; re-check relevance for UK/Canada before activating.
A31: Fuel (Nutrition) | B31: nutrition plan | C31: Exact | E31: =IF(D31="","No Data",INDEX('Bid Tiers'!$A$4:$A$7,MATCH(D31,'Bid Tiers'!$B$4:$B$7,1))) -> No Data | F31: =IF(D31="",0.3,INDEX('Bid Tiers'!$E$4:$E$7,MATCH(D31,'Bid Tiers'!$B$4:$B$7,1))) -> 0.3
A32: Fuel (Nutrition) | B32: cooking | C32: Exact | D32: 57 | E32: =IF(D32="","No Data",INDEX('Bid Tiers'!$A$4:$A$7,MATCH(D32,'Bid Tiers'!$B$4:$B$7,1))) -> Tier A — Head Term | F32: =IF(D32="",0.3,INDEX('Bid Tiers'!$E$4:$E$7,MATCH(D32,'Bid Tiers'!$B$4:$B$7,1))) -> 3
A33: Fuel (Nutrition) | B33: recipes | C33: Exact | D33: 5 | E33: =IF(D33="","No Data",INDEX('Bid Tiers'!$A$4:$A$7,MATCH(D33,'Bid Tiers'!$B$4:$B$7,1))) -> Tier D — Below Threshold (<5) | F33: =IF(D33="",0.3,INDEX('Bid Tiers'!$E$4:$E$7,MATCH(D33,'Bid Tiers'!$B$4:$B$7,1))) -> 0.6
A34: Fuel (Nutrition) | B34: meals | C34: Exact | D34: 5 | E34: =IF(D34="","No Data",INDEX('Bid Tiers'!$A$4:$A$7,MATCH(D34,'Bid Tiers'!$B$4:$B$7,1))) -> Tier D — Below Threshold (<5) | F34: =IF(D34="",0.3,INDEX('Bid Tiers'!$E$4:$E$7,MATCH(D34,'Bid Tiers'!$B$4:$B$7,1))) -> 0.6
A35: Fuel (Nutrition) | B35: cook | C35: Exact | D35: 48 | E35: =IF(D35="","No Data",INDEX('Bid Tiers'!$A$4:$A$7,MATCH(D35,'Bid Tiers'!$B$4:$B$7,1))) -> Tier A — Head Term | F35: =IF(D35="",0.3,INDEX('Bid Tiers'!$E$4:$E$7,MATCH(D35,'Bid Tiers'!$B$4:$B$7,1))) -> 3
A36: Fuel (Nutrition) | B36: dinner | C36: Exact | D36: 6 | E36: =IF(D36="","No Data",INDEX('Bid Tiers'!$A$4:$A$7,MATCH(D36,'Bid Tiers'!$B$4:$B$7,1))) -> Tier C — Long-Tail | F36: =IF(D36="",0.3,INDEX('Bid Tiers'!$E$4:$E$7,MATCH(D36,'Bid Tiers'!$B$4:$B$7,1))) -> 0.9
A37: Fuel (Nutrition) | B37: breakfast | C37: Exact | D37: 9 | E37: =IF(D37="","No Data",INDEX('Bid Tiers'!$A$4:$A$7,MATCH(D37,'Bid Tiers'!$B$4:$B$7,1))) -> Tier C — Long-Tail | F37: =IF(D37="",0.3,INDEX('Bid Tiers'!$E$4:$E$7,MATCH(D37,'Bid Tiers'!$B$4:$B$7,1))) -> 0.9
A38: Fuel (Nutrition) | B38: lunch | C38: Exact | D38: 8 | E38: =IF(D38="","No Data",INDEX('Bid Tiers'!$A$4:$A$7,MATCH(D38,'Bid Tiers'!$B$4:$B$7,1))) -> Tier C — Long-Tail | F38: =IF(D38="",0.3,INDEX('Bid Tiers'!$E$4:$E$7,MATCH(D38,'Bid Tiers'!$B$4:$B$7,1))) -> 0.9
A39: Fuel (Nutrition) | B39: prep | C39: Exact | D39: 5 | E39: =IF(D39="","No Data",INDEX('Bid Tiers'!$A$4:$A$7,MATCH(D39,'Bid Tiers'!$B$4:$B$7,1))) -> Tier D — Below Threshold (<5) | F39: =IF(D39="",0.3,INDEX('Bid Tiers'!$E$4:$E$7,MATCH(D39,'Bid Tiers'!$B$4:$B$7,1))) -> 0.6
A40: Fuel (Nutrition) | B40: carb counter | C40: Exact | D40: 5 | E40: =IF(D40="","No Data",INDEX('Bid Tiers'!$A$4:$A$7,MATCH(D40,'Bid Tiers'!$B$4:$B$7,1))) -> Tier D — Below Threshold (<5) | F40: =IF(D40="",0.3,INDEX('Bid Tiers'!$E$4:$E$7,MATCH(D40,'Bid Tiers'!$B$4:$B$7,1))) -> 0.6
...

Sheet Canada
A1: Bluom — Apple Search Ads — Canada
A2: Draft ad group / keyword / bid structure. Edit Match Type or Notes freely — Tier and Suggested Max CPT are formulas pulling from the 'Bid Tiers' tab.
A3: Ad Group | B3: Keyword | C3: Match Type | D3: Popularity Score | E3: Tier | F3: Suggested Max CPT ($) | G3: Notes
A4: Brand | B4: bluom | C4: Exact | D4: — | E4: Brand | F4: 0.4 | G4: Defensive brand term — no organic competition expected.
A5: Brand | B5: bluom app | C5: Exact | D5: — | E5: Brand | F5: 0.4 | G5: Defensive brand term.
A6: Brand | B6: bluom health os | C6: Exact | D6: — | E6: Brand | F6: 0.4 | G6: Defensive brand term — matches your new positioning line.
A7: Discovery | B7: [Search Match ON — no explicit keywords] | C7: Search Match | D7: — | E7: — | F7: 0.5 | G7: Let Apple surface new search terms; review weekly and graduate winners into the matching Exact Match group.
A8: AI Coach & Scanner | B8: ai fitness | C8: Exact | D8: 20 | E8: =IF(D8="","No Data",INDEX('Bid Tiers'!$A$4:$A$7,MATCH(D8,'Bid Tiers'!$B$4:$B$7,1))) -> Tier B — Mid Volume | F8: =IF(D8="",0.3,INDEX('Bid Tiers'!$E$4:$E$7,MATCH(D8,'Bid Tiers'!$B$4:$B$7,1))) -> 1.5
A9: AI Coach & Scanner | B9: AI Calorie | C9: Exact | E9: =IF(D9="","No Data",INDEX('Bid Tiers'!$A$4:$A$7,MATCH(D9,'Bid Tiers'!$B$4:$B$7,1))) -> No Data | F9: =IF(D9="",0.3,INDEX('Bid Tiers'!$E$4:$E$7,MATCH(D9,'Bid Tiers'!$B$4:$B$7,1))) -> 0.3
A10: AI Coach & Scanner | B10: AI Calories | C10: Exact | E10: =IF(D10="","No Data",INDEX('Bid Tiers'!$A$4:$A$7,MATCH(D10,'Bid Tiers'!$B$4:$B$7,1))) -> No Data | F10: =IF(D10="",0.3,INDEX('Bid Tiers'!$E$4:$E$7,MATCH(D10,'Bid Tiers'!$B$4:$B$7,1))) -> 0.3
A11: AI Coach & Scanner | B11: AI nutrition | C11: Exact | D11: 5 | E11: =IF(D11="","No Data",INDEX('Bid Tiers'!$A$4:$A$7,MATCH(D11,'Bid Tiers'!$B$4:$B$7,1))) -> Tier D — Below Threshold (<5) | F11: =IF(D11="",0.3,INDEX('Bid Tiers'!$E$4:$E$7,MATCH(D11,'Bid Tiers'!$B$4:$B$7,1))) -> 0.6
A12: AI Coach & Scanner | B12: ai food | C12: Exact | D12: 5 | E12: =IF(D12="","No Data",INDEX('Bid Tiers'!$A$4:$A$7,MATCH(D12,'Bid Tiers'!$B$4:$B$7,1))) -> Tier D — Below Threshold (<5) | F12: =IF(D12="",0.3,INDEX('Bid Tiers'!$E$4:$E$7,MATCH(D12,'Bid Tiers'!$B$4:$B$7,1))) -> 0.6
A13: AI Coach & Scanner | B13: meal scanner | C13: Exact | E13: =IF(D13="","No Data",INDEX('Bid Tiers'!$A$4:$A$7,MATCH(D13,'Bid Tiers'!$B$4:$B$7,1))) -> No Data | F13: =IF(D13="",0.3,INDEX('Bid Tiers'!$E$4:$E$7,MATCH(D13,'Bid Tiers'!$B$4:$B$7,1))) -> 0.3
A14: AI Coach & Scanner | B14: ai coach | C14: Exact | D14: 5 | E14: =IF(D14="","No Data",INDEX('Bid Tiers'!$A$4:$A$7,MATCH(D14,'Bid Tiers'!$B$4:$B$7,1))) -> Tier D — Below Threshold (<5) | F14: =IF(D14="",0.3,INDEX('Bid Tiers'!$E$4:$E$7,MATCH(D14,'Bid Tiers'!$B$4:$B$7,1))) -> 0.6
A15: AI Coach & Scanner | B15: scanner | C15: Exact | D15: 59 | E15: =IF(D15="","No Data",INDEX('Bid Tiers'!$A$4:$A$7,MATCH(D15,'Bid Tiers'!$B$4:$B$7,1))) -> Tier A — Head Term | F15: =IF(D15="",0.3,INDEX('Bid Tiers'!$E$4:$E$7,MATCH(D15,'Bid Tiers'!$B$4:$B$7,1))) -> 3 | G15: Broad head term for the AI photo/food scanning feature — Bluom's core differentiator. Worth the higher bid.
A16: AI Coach & Scanner | B16: food scanner | C16: Exact | D16: 39 | E16: =IF(D16="","No Data",INDEX('Bid Tiers'!$A$4:$A$7,MATCH(D16,'Bid Tiers'!$B$4:$B$7,1))) -> Tier B — Mid Volume | F16: =IF(D16="",0.3,INDEX('Bid Tiers'!$E$4:$E$7,MATCH(D16,'Bid Tiers'!$B$4:$B$7,1))) -> 1.5
A17: AI Coach & Scanner | B17: photo calorie | C17: Exact | E17: =IF(D17="","No Data",INDEX('Bid Tiers'!$A$4:$A$7,MATCH(D17,'Bid Tiers'!$B$4:$B$7,1))) -> No Data | F17: =IF(D17="",0.3,INDEX('Bid Tiers'!$E$4:$E$7,MATCH(D17,'Bid Tiers'!$B$4:$B$7,1))) -> 0.3
A18: AI Coach & Scanner | B18: nutrition scanner | C18: Exact | D18: 5 | E18: =IF(D18="","No Data",INDEX('Bid Tiers'!$A$4:$A$7,MATCH(D18,'Bid Tiers'!$B$4:$B$7,1))) -> Tier D — Below Threshold (<5) | F18: =IF(D18="",0.3,INDEX('Bid Tiers'!$E$4:$E$7,MATCH(D18,'Bid Tiers'!$B$4:$B$7,1))) -> 0.6
A19: Fuel (Nutrition) | B19: food | C19: Exact | D19: 56 | E19: =IF(D19="","No Data",INDEX('Bid Tiers'!$A$4:$A$7,MATCH(D19,'Bid Tiers'!$B$4:$B$7,1))) -> Tier A — Head Term | F19: =IF(D19="",0.3,INDEX('Bid Tiers'!$E$4:$E$7,MATCH(D19,'Bid Tiers'!$B$4:$B$7,1))) -> 3
A20: Fuel (Nutrition) | B20: diet | C20: Exact | D20: 5 | E20: =IF(D20="","No Data",INDEX('Bid Tiers'!$A$4:$A$7,MATCH(D20,'Bid Tiers'!$B$4:$B$7,1))) -> Tier D — Below Threshold (<5) | F20: =IF(D20="",0.3,INDEX('Bid Tiers'!$E$4:$E$7,MATCH(D20,'Bid Tiers'!$B$4:$B$7,1))) -> 0.6
A21: Fuel (Nutrition) | B21: weight | C21: Exact | D21: 5 | E21: =IF(D21="","No Data",INDEX('Bid Tiers'!$A$4:$A$7,MATCH(D21,'Bid Tiers'!$B$4:$B$7,1))) -> Tier D — Below Threshold (<5) | F21: =IF(D21="",0.3,INDEX('Bid Tiers'!$E$4:$E$7,MATCH(D21,'Bid Tiers'!$B$4:$B$7,1))) -> 0.6
A22: Fuel (Nutrition) | B22: protein | C22: Exact | D22: 5 | E22: =IF(D22="","No Data",INDEX('Bid Tiers'!$A$4:$A$7,MATCH(D22,'Bid Tiers'!$B$4:$B$7,1))) -> Tier D — Below Threshold (<5) | F22: =IF(D22="",0.3,INDEX('Bid Tiers'!$E$4:$E$7,MATCH(D22,'Bid Tiers'!$B$4:$B$7,1))) -> 0.6
A23: Fuel (Nutrition) | B23: eating | C23: Exact | D23: 5 | E23: =IF(D23="","No Data",INDEX('Bid Tiers'!$A$4:$A$7,MATCH(D23,'Bid Tiers'!$B$4:$B$7,1))) -> Tier D — Below Threshold (<5) | F23: =IF(D23="",0.3,INDEX('Bid Tiers'!$E$4:$E$7,MATCH(D23,'Bid Tiers'!$B$4:$B$7,1))) -> 0.6
A24: Fuel (Nutrition) | B24: macro | C24: Exact | D24: 38 | E24: =IF(D24="","No Data",INDEX('Bid Tiers'!$A$4:$A$7,MATCH(D24,'Bid Tiers'!$B$4:$B$7,1))) -> Tier B — Mid Volume | F24: =IF(D24="",0.3,INDEX('Bid Tiers'!$E$4:$E$7,MATCH(D24,'Bid Tiers'!$B$4:$B$7,1))) -> 1.5
A25: Fuel (Nutrition) | B25: macros | C25: Exact | D25: 5 | E25: =IF(D25="","No Data",INDEX('Bid Tiers'!$A$4:$A$7,MATCH(D25,'Bid Tiers'!$B$4:$B$7,1))) -> Tier D — Below Threshold (<5) | F25: =IF(D25="",0.3,INDEX('Bid Tiers'!$E$4:$E$7,MATCH(D25,'Bid Tiers'!$B$4:$B$7,1))) -> 0.6
A26: Fuel (Nutrition) | B26: macros tracker | C26: Exact | D26: 5 | E26: =IF(D26="","No Data",INDEX('Bid Tiers'!$A$4:$A$7,MATCH(D26,'Bid Tiers'!$B$4:$B$7,1))) -> Tier D — Below Threshold (<5) | F26: =IF(D26="",0.3,INDEX('Bid Tiers'!$E$4:$E$7,MATCH(D26,'Bid Tiers'!$B$4:$B$7,1))) -> 0.6
A27: Fuel (Nutrition) | B27: macro tracker | C27: Exact | D27: 46 | E27: =IF(D27="","No Data",INDEX('Bid Tiers'!$A$4:$A$7,MATCH(D27,'Bid Tiers'!$B$4:$B$7,1))) -> Tier A — Head Term | F27: =IF(D27="",0.3,INDEX('Bid Tiers'!$E$4:$E$7,MATCH(D27,'Bid Tiers'!$B$4:$B$7,1))) -> 3
A28: Fuel (Nutrition) | B28: meal tracker | C28: Exact | D28: 5 | E28: =IF(D28="","No Data",INDEX('Bid Tiers'!$A$4:$A$7,MATCH(D28,'Bid Tiers'!$B$4:$B$7,1))) -> Tier D — Below Threshold (<5) | F28: =IF(D28="",0.3,INDEX('Bid Tiers'!$E$4:$E$7,MATCH(D28,'Bid Tiers'!$B$4:$B$7,1))) -> 0.6
A29: Fuel (Nutrition) | B29: meal tracker free | C29: Exact | D29: 5 | E29: =IF(D29="","No Data",INDEX('Bid Tiers'!$A$4:$A$7,MATCH(D29,'Bid Tiers'!$B$4:$B$7,1))) -> Tier D — Below Threshold (<5) | F29: =IF(D29="",0.3,INDEX('Bid Tiers'!$E$4:$E$7,MATCH(D29,'Bid Tiers'!$B$4:$B$7,1))) -> 0.6
A30: Fuel (Nutrition) | B30: plan personalizado | C30: Exact | E30: =IF(D30="","No Data",INDEX('Bid Tiers'!$A$4:$A$7,MATCH(D30,'Bid Tiers'!$B$4:$B$7,1))) -> No Data | F30: =IF(D30="",0.3,INDEX('Bid Tiers'!$E$4:$E$7,MATCH(D30,'Bid Tiers'!$B$4:$B$7,1))) -> 0.3 | G30: Spanish-language query appearing in English-market data — likely Hispanic/bilingual searchers. Keep for USA; re-check relevance for UK/Canada before activating.
A31: Fuel (Nutrition) | B31: nutrition plan | C31: Exact | E31: =IF(D31="","No Data",INDEX('Bid Tiers'!$A$4:$A$7,MATCH(D31,'Bid Tiers'!$B$4:$B$7,1))) -> No Data | F31: =IF(D31="",0.3,INDEX('Bid Tiers'!$E$4:$E$7,MATCH(D31,'Bid Tiers'!$B$4:$B$7,1))) -> 0.3
A32: Fuel (Nutrition) | B32: cooking | C32: Exact | D32: 57 | E32: =IF(D32="","No Data",INDEX('Bid Tiers'!$A$4:$A$7,MATCH(D32,'Bid Tiers'!$B$4:$B$7,1))) -> Tier A — Head Term | F32: =IF(D32="",0.3,INDEX('Bid Tiers'!$E$4:$E$7,MATCH(D32,'Bid Tiers'!$B$4:$B$7,1))) -> 3
A33: Fuel (Nutrition) | B33: recipes | C33: Exact | D33: 5 | E33: =IF(D33="","No Data",INDEX('Bid Tiers'!$A$4:$A$7,MATCH(D33,'Bid Tiers'!$B$4:$B$7,1))) -> Tier D — Below Threshold (<5) | F33: =IF(D33="",0.3,INDEX('Bid Tiers'!$E$4:$E$7,MATCH(D33,'Bid Tiers'!$B$4:$B$7,1))) -> 0.6
A34: Fuel (Nutrition) | B34: meals | C34: Exact | D34: 5 | E34: =IF(D34="","No Data",INDEX('Bid Tiers'!$A$4:$A$7,MATCH(D34,'Bid Tiers'!$B$4:$B$7,1))) -> Tier D — Below Threshold (<5) | F34: =IF(D34="",0.3,INDEX('Bid Tiers'!$E$4:$E$7,MATCH(D34,'Bid Tiers'!$B$4:$B$7,1))) -> 0.6
A35: Fuel (Nutrition) | B35: cook | C35: Exact | D35: 35 | E35: =IF(D35="","No Data",INDEX('Bid Tiers'!$A$4:$A$7,MATCH(D35,'Bid Tiers'!$B$4:$B$7,1))) -> Tier B — Mid Volume | F35: =IF(D35="",0.3,INDEX('Bid Tiers'!$E$4:$E$7,MATCH(D35,'Bid Tiers'!$B$4:$B$7,1))) -> 1.5
A36: Fuel (Nutrition) | B36: dinner | C36: Exact | D36: 15 | E36: =IF(D36="","No Data",INDEX('Bid Tiers'!$A$4:$A$7,MATCH(D36,'Bid Tiers'!$B$4:$B$7,1))) -> Tier C — Long-Tail | F36: =IF(D36="",0.3,INDEX('Bid Tiers'!$E$4:$E$7,MATCH(D36,'Bid Tiers'!$B$4:$B$7,1))) -> 0.9
A37: Fuel (Nutrition) | B37: breakfast | C37: Exact | D37: 5 | E37: =IF(D37="","No Data",INDEX('Bid Tiers'!$A$4:$A$7,MATCH(D37,'Bid Tiers'!$B$4:$B$7,1))) -> Tier D — Below Threshold (<5) | F37: =IF(D37="",0.3,INDEX('Bid Tiers'!$E$4:$E$7,MATCH(D37,'Bid Tiers'!$B$4:$B$7,1))) -> 0.6
A38: Fuel (Nutrition) | B38: lunch | C38: Exact | D38: 5 | E38: =IF(D38="","No Data",INDEX('Bid Tiers'!$A$4:$A$7,MATCH(D38,'Bid Tiers'!$B$4:$B$7,1))) -> Tier D — Below Threshold (<5) | F38: =IF(D38="",0.3,INDEX('Bid Tiers'!$E$4:$E$7,MATCH(D38,'Bid Tiers'!$B$4:$B$7,1))) -> 0.6
A39: Fuel (Nutrition) | B39: prep | C39: Exact | D39: 5 | E39: =IF(D39="","No Data",INDEX('Bid Tiers'!$A$4:$A$7,MATCH(D39,'Bid Tiers'!$B$4:$B$7,1))) -> Tier D — Below Threshold (<5) | F39: =IF(D39="",0.3,INDEX('Bid Tiers'!$E$4:$E$7,MATCH(D39,'Bid Tiers'!$B$4:$B$7,1))) -> 0.6
A40: Fuel (Nutrition) | B40: carb counter | C40: Exact | D40: 5 | E40: =IF(D40="","No Data",INDEX('Bid Tiers'!$A$4:$A$7,MATCH(D40,'Bid Tiers'!$B$4:$B$7,1))) -> Tier D — Below Threshold (<5) | F40: =IF(D40="",0.3,INDEX('Bid Tiers'!$E$4:$E$7,MATCH(D40,'Bid Tiers'!$B$4:$B$7,1))) -> 0.6
...
