Workbook

Sheet Read Me
A1: Bluom — Apple Search Ads Campaign Drafts (Europe)
A2: Germany, Netherlands, Spain, France, Austria, Belgium, Denmark, Italy, Norway, Sweden, Switzerland — built from the 'ASO Clean + New Markets (Sep 5)' tab of your Keywords Google Sheet
A4: What this is
A5: Companion workbook to Bluom_Apple_Search_Ads_Drafts.xlsx (USA/UK/Canada). Same ad-group structure — Brand, Discovery, AI Coach & Scanner, Fuel (Nutrition), Move (Fitness), Plans (Habits), Wellness (Mind & Sleep), Women's Health, Fasting & Metabolic, Tools (Calculators) — applied to 11 more markets, each keyword translated/classified into the matching group. Tabs are ordered Germany, Netherlands, Spain, France first (as requested), then the remaining seven markets.
A7: IMPORTANT — two different data sources, two different tiering methods
A8: Your sheet does NOT have the same Apple Search Ads popularity score (0-100) for every market. Only Austria, Belgium, and Switzerland have it (column 'Search Ads (Apple, ASOMobile)'). For those three, tiering works exactly like the USA/UK/Canada workbook — see the 'Bid Tiers (Popularity Score)' tab.
A9: Germany and Netherlands have Apple's own 'Apple Volume' figure but NOT the 0-100 popularity score, so those two tabs rank keywords by Apple Volume instead — a real Apple-sourced number, just a different scale, so it can't share the same fixed thresholds as the score-based markets.
A10: Denmark, France, Italy, Norway, Spain, and Sweden have neither — only a single combined Google/Semrush search-volume figure. Those six tabs rank keywords by that volume. It is NOT Apple-specific, just the best available signal for those markets in your sheet.
A11: Because Apple Volume and Semrush Volume are raw counts that vary wildly by market size (Germany's numbers are nothing like Norway's), those 8 tabs use RELATIVE tiers computed from each tab's own data — Tier A is roughly the top 15% of that market's own keyword list, not an absolute score. See the 'Bid Tiers (Relative Volume)' tab. Tier labels are named differently on purpose ('Top 15%' vs 'Head Term') so the two systems are never confused.
A13: Translation & classification
A14: Each non-English keyword was translated and placed into the ad group matching its meaning (e.g. 'kalorienzähler' / German for calorie counter → Fuel; 'coach' / French for coach → AI Coach & Scanner; 'søvn' / Danish for sleep → Wellness). A handful of keywords are flagged in the Notes column where the source data itself looked like a typo or mistranslation from the ASO tool (e.g. 'Ausbildung' in German usually means 'apprenticeship', not 'training') — kept verbatim since that may be literally what people searched.
A15: A few keywords repeated within one country's own export (duplicates) were kept once, not twice.
... A19: Suggested Max CPT ranges here lean lower than the US/UK/Canada workbook, reflecting generally lower CPCs observed across these markets in your Semrush data — still estimates, not Apple auction data. Start low.

Sheet Campaign Plan
A1: Campaign Plan — same ad-group structure as USA/UK/Canada, applied per market
A3: One Advanced campaign per country, each containing these ad groups:
A5: Ad Group | B5: Purpose | C5: Search Match | D5: Notes
A6: Brand | B6: Protects 'bluom' / 'bluom app' / 'bluom health os' from competitors bidding on your own name. | C6: Off | D6: Same brand terms across every market — localize only if you register market-specific taglines.
A7: Discovery | B7: Search Match ON, zero explicit keywords. | C7: On | D7: Especially valuable in these markets since keyword research here is thinner than USA/UK/Canada — let Apple surface real local search terms.
A8: AI Coach & Scanner | B8: Coach/coaching concept + AI scanning differentiator. | C8: Off | D8: Highest strategic priority even at low volume.
A9: Fuel (Nutrition) | B9: Food, diet, macro, calorie, weight, grocery-list terms. | C9: Off | D9: Largest group in every market by keyword count.
A10: Move (Fitness) | B10: Workouts, gym, running, cycling, training-plan terms. | C10: Off | D10: Broad category, generally the highest absolute search volume per market.
A11: Plans (Habits) | B11: Habit building and the generic 'tracker' term. | C11: Off | D11: 'tracker' alone is very generic — consider dropping or tight negatives, same caution as USA/UK/Canada.
A12: Wellness (Mind & Sleep) | B12: Sleep, meditation, brain games, mood, hydration, general 'health' terms. | C12: Off | D12: Broadest group by keyword count in most markets.
A13: Women's Health | B13: Period, cycle, menstruation terms. | C13: Off | D13: Thin in most of these markets' keyword data — a Discovery-led opportunity.
A14: Fasting & Metabolic | B14: Fasting terms. | C14: Off | D14: Small in these markets compared to USA/UK/Canada — matches your Fasting blog content pillar regardless.
A15: Tools (Calculators) | B15: BMI calculator (only present in the Netherlands data). | C15: Off | D15: Very thin here — most markets have no calculator-intent keywords in your export at all.
A17: Data gaps to flag for Jorge:
A18: • No Apple popularity score for DE/NL/FR/ES/IT/NO/SE/DK — only AT/BE/CH have it. See Read Me.
A19: • Tools (Calculators) group is nearly empty outside the Netherlands — your keyword research for these markets doesn't cover calculator-intent terms the way USA/UK/Canada does.
A20: • Women's Health and Fasting & Metabolic are thin across most of these markets — worth a dedicated keyword research pass if you want to run those ad groups seriously here.

Sheet Bid Tiers (Popularity Score)
A1: Bid Tiers — Austria, Belgium, Switzerland (these three have Apple's 0-100 popularity score)
A3: Tier | B3: Min Score | C3: Max Score | D3: Sugg. Min CPT ($) | E3: Sugg. Max CPT ($) | F3: Description
A4: Tier D — Below Threshold (<5) | B4: 0 | C4: 5 | D4: 0.25 | E4: 0.5 | F4: Apple's own '<5' floor value.
A5: Tier C — Long-Tail | B5: 6 | C5: 19 | D5: 0.4 | E5: 0.75 | F5: Real but low popularity.
A6: Tier B — Mid Volume | B6: 20 | C6: 44 | D6: 0.65 | E6: 1.25 | F6: Moderate competition.
A7: Tier A — Head Term | B7: 45 | C7: 100 | D7: 1.25 | E7: 2.5 | F7: Highest popularity in-market.

Sheet Bid Tiers (Relative Volume)
A1: Bid Tiers — Germany, Netherlands, Denmark, France, Italy, Norway, Spain, Sweden
A2: These markets have no Apple popularity score, so each country tab ranks its OWN keywords into relative tiers (Top 15% / next 25% / next 30% / bottom 30%) using that tab's own volume column — a different keyword list in Germany won't share thresholds with Norway's.
A4: Tier | B4: Sugg. Min CPT ($) | C4: Sugg. Max CPT ($) | D4: Description
A5: Tier D (Bottom 30%) | B5: 0.2 | C5: 0.4 | D5: Lowest relative volume in this market's own list, including zero/no-data terms.
A6: Tier C (Top 70%) | B6: 0.35 | C6: 0.65 | D6: Below-median but real volume.
A7: Tier B (Top 40%) | B7: 0.55 | C7: 1 | D7: Above-median volume for this market.
A8: Tier A (Top 15%) | B8: 0.9 | C8: 1.9 | D8: This market's own highest-volume terms.
A9: No Data | B9: 0.2 | C9: 0.2 | D9: No volume reported for this keyword in this market.

Sheet Germany
A1: Bluom — Apple Search Ads — Germany | J1: Thresholds (from this tab's own data):
A2: Ranked by Apple's own volume figure, relative to other keywords in this market (see Bid Tiers (Relative Volume)). | J2: P85 | K2: =PERCENTILE(D8:D56,0.85) -> 475.3
A3: Ad Group | B3: Keyword | C3: Match Type | D3: Apple Volume (relative) | E3: Tier | F3: Suggested Max CPT ($) | G3: Notes | J3: P60 | K3: =PERCENTILE(D8:D56,0.6) -> 222.4
A4: Brand | B4: bluom | C4: Exact | D4: — | E4: Brand | F4: 0.3 | G4: Defensive brand term. | J4: P30 | K4: =PERCENTILE(D8:D56,0.3) -> 26.7
A5: Brand | B5: bluom app | C5: Exact | D5: — | E5: Brand | F5: 0.3 | G5: Defensive brand term.
A6: Brand | B6: bluom health os | C6: Exact | D6: — | E6: Brand | F6: 0.3 | G6: Defensive brand term — matches your new positioning line.
A7: Discovery | B7: [Search Match ON — no explicit keywords] | C7: Search Match | D7: — | E7: — | F7: 0.4 | G7: Especially useful here — let Apple surface real local search terms this thinner keyword list might be missing.
A8: Fuel (Nutrition) | B8: weight tracker | C8: Exact | D8: 302 | E8: =IF(D8="","No Data",IF(D8>=$K$2,"Tier A (Top 15%)",IF(D8>=$K$3,"Tier B (Top 40%)",IF(D8>=$K$4,"Tier C (Top 70%)","Tier D (Bottom 30%)")))) -> Tier B (Top 40%) | F8: =VLOOKUP(E8,'Bid Tiers (Relative Volume)'!$A$5:$C$9,3,FALSE()) -> 1
A9: Fuel (Nutrition) | B9: Kochen | C9: Exact | D9: 755 | E9: =IF(D9="","No Data",IF(D9>=$K$2,"Tier A (Top 15%)",IF(D9>=$K$3,"Tier B (Top 40%)",IF(D9>=$K$4,"Tier C (Top 70%)","Tier D (Bottom 30%)")))) -> Tier A (Top 15%) | F9: =VLOOKUP(E9,'Bid Tiers (Relative Volume)'!$A$5:$C$9,3,FALSE()) -> 1.9
A10: Fuel (Nutrition) | B10: kalorien | C10: Exact | D10: 284 | E10: =IF(D10="","No Data",IF(D10>=$K$2,"Tier A (Top 15%)",IF(D10>=$K$3,"Tier B (Top 40%)",IF(D10>=$K$4,"Tier C (Top 70%)","Tier D (Bottom 30%)")))) -> Tier B (Top 40%) | F10: =VLOOKUP(E10,'Bid Tiers (Relative Volume)'!$A$5:$C$9,3,FALSE()) -> 1
A11: Fuel (Nutrition) | B11: ernährung | C11: Exact | D11: 219 | E11: =IF(D11="","No Data",IF(D11>=$K$2,"Tier A (Top 15%)",IF(D11>=$K$3,"Tier B (Top 40%)",IF(D11>=$K$4,"Tier C (Top 70%)","Tier D (Bottom 30%)")))) -> Tier C (Top 70%) | F11: =VLOOKUP(E11,'Bid Tiers (Relative Volume)'!$A$5:$C$9,3,FALSE()) -> 0.65
A12: Fuel (Nutrition) | B12: macro | C12: Exact | D12: 24 | E12: =IF(D12="","No Data",IF(D12>=$K$2,"Tier A (Top 15%)",IF(D12>=$K$3,"Tier B (Top 40%)",IF(D12>=$K$4,"Tier C (Top 70%)","Tier D (Bottom 30%)")))) -> Tier D (Bottom 30%) | F12: =VLOOKUP(E12,'Bid Tiers (Relative Volume)'!$A$5:$C$9,3,FALSE()) -> 0.4
A13: Fuel (Nutrition) | B13: gewicht | C13: Exact | D13: 192 | E13: =IF(D13="","No Data",IF(D13>=$K$2,"Tier A (Top 15%)",IF(D13>=$K$3,"Tier B (Top 40%)",IF(D13>=$K$4,"Tier C (Top 70%)","Tier D (Bottom 30%)")))) -> Tier C (Top 70%) | F13: =VLOOKUP(E13,'Bid Tiers (Relative Volume)'!$A$5:$C$9,3,FALSE()) -> 0.65
A14: Fuel (Nutrition) | B14: diät | C14: Exact | D14: 130 | E14: =IF(D14="","No Data",IF(D14>=$K$2,"Tier A (Top 15%)",IF(D14>=$K$3,"Tier B (Top 40%)",IF(D14>=$K$4,"Tier C (Top 70%)","Tier D (Bottom 30%)")))) -> Tier C (Top 70%) | F14: =VLOOKUP(E14,'Bid Tiers (Relative Volume)'!$A$5:$C$9,3,FALSE()) -> 0.65
A15: Fuel (Nutrition) | B15: kalorientracker | C15: Exact | D15: 93 | E15: =IF(D15="","No Data",IF(D15>=$K$2,"Tier A (Top 15%)",IF(D15>=$K$3,"Tier B (Top 40%)",IF(D15>=$K$4,"Tier C (Top 70%)","Tier D (Bottom 30%)")))) -> Tier C (Top 70%) | F15: =VLOOKUP(E15,'Bid Tiers (Relative Volume)'!$A$5:$C$9,3,FALSE()) -> 0.65
A16: Fuel (Nutrition) | B16: diet | C16: Exact | D16: 79 | E16: =IF(D16="","No Data",IF(D16>=$K$2,"Tier A (Top 15%)",IF(D16>=$K$3,"Tier B (Top 40%)",IF(D16>=$K$4,"Tier C (Top 70%)","Tier D (Bottom 30%)")))) -> Tier C (Top 70%) | F16: =VLOOKUP(E16,'Bid Tiers (Relative Volume)'!$A$5:$C$9,3,FALSE()) -> 0.65
A17: Fuel (Nutrition) | B17: macro tracker | C17: Exact | D17: 218 | E17: =IF(D17="","No Data",IF(D17>=$K$2,"Tier A (Top 15%)",IF(D17>=$K$3,"Tier B (Top 40%)",IF(D17>=$K$4,"Tier C (Top 70%)","Tier D (Bottom 30%)")))) -> Tier C (Top 70%) | F17: =VLOOKUP(E17,'Bid Tiers (Relative Volume)'!$A$5:$C$9,3,FALSE()) -> 0.65
A18: Fuel (Nutrition) | B18: macros | C18: Exact | D18: 66 | E18: =IF(D18="","No Data",IF(D18>=$K$2,"Tier A (Top 15%)",IF(D18>=$K$3,"Tier B (Top 40%)",IF(D18>=$K$4,"Tier C (Top 70%)","Tier D (Bottom 30%)")))) -> Tier C (Top 70%) | F18: =VLOOKUP(E18,'Bid Tiers (Relative Volume)'!$A$5:$C$9,3,FALSE()) -> 0.65
A19: Fuel (Nutrition) | B19: weight loss | C19: Exact | D19: 183 | E19: =IF(D19="","No Data",IF(D19>=$K$2,"Tier A (Top 15%)",IF(D19>=$K$3,"Tier B (Top 40%)",IF(D19>=$K$4,"Tier C (Top 70%)","Tier D (Bottom 30%)")))) -> Tier C (Top 70%) | F19: =VLOOKUP(E19,'Bid Tiers (Relative Volume)'!$A$5:$C$9,3,FALSE()) -> 0.65
... A26: Move (Fitness) | B26: run | C26: Exact | D26: 66 | E26: =IF(D26="","No Data",IF(D26>=$K$2,"Tier A (Top 15%)",IF(D26>=$K$3,"Tier B (Top 40%)",IF(D26>=$K$4,"Tier C (Top 70%)","Tier D (Bottom 30%)")))) -> Tier C (Top 70%) | F26: =VLOOKUP(E26,'Bid Tiers (Relative Volume)'!$A$5:$C$9,3,FALSE()) -> 0.65
A27: Move (Fitness) | B27: workout timer | C27: Exact | E27: =IF(D27="","No Data",IF(D27>=$K$2,"Tier A (Top 15%)",IF(D27>=$K$3,"Tier B (Top 40%)",IF(D27>=$K$4,"Tier C (Top 70%)","Tier D (Bottom 30%)")))) -> No Data | F27: =VLOOKUP(E27,'Bid Tiers (Relative Volume)'!$A$5:$C$9,3,FALSE()) -> 0.2
A28: Move (Fitness) | B28: step counter | C28: Exact | D28: 236 | E28: =IF(D28="","No Data",IF(D28>=$K$2,"Tier A (Top 15%)",IF(D28>=$K$3,"Tier B (Top 40%)",IF(D28>=$K$4,"Tier C (Top 70%)","Tier D (Bottom 30%)")))) -> Tier B (Top 40%) | F28: =VLOOKUP(E28,'Bid Tiers (Relative Volume)'!$A$5:$C$9,3,FALSE()) -> 1
A29: Move (Fitness) | B29: muskeln | C29: Exact | D29: 51 | E29: =IF(D29="","No Data",IF(D29>=$K$2,"Tier A (Top 15%)",IF(D29>=$K$3,"Tier B (Top 40%)",IF(D29>=$K$4,"Tier C (Top 70%)","Tier D (Bottom 30%)")))) -> Tier C (Top 70%) | F29: =VLOOKUP(E29,'Bid Tiers (Relative Volume)'!$A$5:$C$9,3,FALSE()) -> 0.65
A30: Move (Fitness) | B30: Ausbildung | C30: Exact | D30: 12 | E30: =IF(D30="","No Data",IF(D30>=$K$2,"Tier A (Top 15%)",IF(D30>=$K$3,"Tier B (Top 40%)",IF(D30>=$K$4,"Tier C (Top 70%)","Tier D (Bottom 30%)")))) -> Tier D (Bottom 30%) | F30: =VLOOKUP(E30,'Bid Tiers (Relative Volume)'!$A$5:$C$9,3,FALSE()) -> 0.4 | G30: German for 'training/apprenticeship' — likely a mistranslation or loose ASO-tool match for 'training', kept as-is from your export.
A31: Move (Fitness) | B31: laufen | C31: Exact | D31: 18 | E31: =IF(D31="","No Data",IF(D31>=$K$2,"Tier A (Top 15%)",IF(D31>=$K$3,"Tier B (Top 40%)",IF(D31>=$K$4,"Tier C (Top 70%)","Tier D (Bottom 30%)")))) -> Tier D (Bottom 30%) | F31: =VLOOKUP(E31,'Bid Tiers (Relative Volume)'!$A$5:$C$9,3,FALSE()) -> 0.4
A32: Move (Fitness) | B32: Wochenplaner | C32: Exact | D32: 0 | E32: =IF(D32="","No Data",IF(D32>=$K$2,"Tier A (Top 15%)",IF(D32>=$K$3,"Tier B (Top 40%)",IF(D32>=$K$4,"Tier C (Top 70%)","Tier D (Bottom 30%)")))) -> Tier D (Bottom 30%) | F32: =VLOOKUP(E32,'Bid Tiers (Relative Volume)'!$A$5:$C$9,3,FALSE()) -> 0.4
A33: Move (Fitness) | B33: exercise | C33: Exact | D33: 4 | E33: =IF(D33="","No Data",IF(D33>=$K$2,"Tier A (Top 15%)",IF(D33>=$K$3,"Tier B (Top 40%)",IF(D33>=$K$4,"Tier C (Top 70%)","Tier D (Bottom 30%)")))) -> Tier D (Bottom 30%) | F33: =VLOOKUP(E33,'Bid Tiers (Relative Volume)'!$A$5:$C$9,3,FALSE()) -> 0.4
A34: Move (Fitness) | B34: exercises | C34: Exact | D34: 1 | E34: =IF(D34="","No Data",IF(D34>=$K$2,"Tier A (Top 15%)",IF(D34>=$K$3,"Tier B (Top 40%)",IF(D34>=$K$4,"Tier C (Top 70%)","Tier D (Bottom 30%)")))) -> Tier D (Bottom 30%) | F34: =VLOOKUP(E34,'Bid Tiers (Relative Volume)'!$A$5:$C$9,3,FALSE()) -> 0.4
A35: Plans (Habits) | B35: tracker | C35: Exact | D35: 443 | E35: =IF(D35="","No Data",IF(D35>=$K$2,"Tier A (Top 15%)",IF(D35>=$K$3,"Tier B (Top 40%)",IF(D35>=$K$4,"Tier C (Top 70%)","Tier D (Bottom 30%)")))) -> Tier B (Top 40%) | F35: =VLOOKUP(E35,'Bid Tiers (Relative Volume)'!$A$5:$C$9,3,FALSE()) -> 1
A36: Plans (Habits) | B36: habit | C36: Exact | D36: 384 | E36: =IF(D36="","No Data",IF(D36>=$K$2,"Tier A (Top 15%)",IF(D36>=$K$3,"Tier B (Top 40%)",IF(D36>=$K$4,"Tier C (Top 70%)","Tier D (Bottom 30%)")))) -> Tier B (Top 40%) | F36: =VLOOKUP(E36,'Bid Tiers (Relative Volume)'!$A$5:$C$9,3,FALSE()) -> 1
A37: Plans (Habits) | B37: habit tracker | C37: Exact | D37: 820 | E37: =IF(D37="","No Data",IF(D37>=$K$2,"Tier A (Top 15%)",IF(D37>=$K$3,"Tier B (Top 40%)",IF(D37>=$K$4,"Tier C (Top 70%)","Tier D (Bottom 30%)")))) -> Tier A (Top 15%) | F37: =VLOOKUP(E37,'Bid Tiers (Relative Volume)'!$A$5:$C$9,3,FALSE()) -> 1.9
A38: Plans (Habits) | B38: Gewohnheitstracker | C38: Exact | D38: 113 | E38: =IF(D38="","No Data",IF(D38>=$K$2,"Tier A (Top 15%)",IF(D38>=$K$3,"Tier B (Top 40%)",IF(D38>=$K$4,"Tier C (Top 70%)","Tier D (Bottom 30%)")))) -> Tier C (Top 70%) | F38: =VLOOKUP(E38,'Bid Tiers (Relative Volume)'!$A$5:$C$9,3,FALSE()) -> 0.65
A39: Plans (Habits) | B39: Gewohnheiten | C39: Exact | D39: 0 | E39: =IF(D39="","No Data",IF(D39>=$K$2,"Tier A (Top 15%)",IF(D39>=$K$3,"Tier B (Top 40%)",IF(D39>=$K$4,"Tier C (Top 70%)","Tier D (Bottom 30%)")))) -> Tier D (Bottom 30%) | F39: =VLOOKUP(E39,'Bid Tiers (Relative Volume)'!$A$5:$C$9,3,FALSE()) -> 0.4
A40: Plans (Habits) | B40: gewohnheit | C40: Exact | D40: 1 | E40: =IF(D40="","No Data",IF(D40>=$K$2,"Tier A (Top 15%)",IF(D40>=$K$3,"Tier B (Top 40%)",IF(D40>=$K$4,"Tier C (Top 70%)","Tier D (Bottom 30%)")))) -> Tier D (Bottom 30%) | F40: =VLOOKUP(E40,'Bid Tiers (Relative Volume)'!$A$5:$C$9,3,FALSE()) -> 0.4
A41: Wellness (Mind & Sleep) | B41: health | C41: Exact | D41: 1947 | E41: =IF(D41="","No Data",IF(D41>=$K$2,"Tier A (Top 15%)",IF(D41>=$K$3,"Tier B (Top 40%)",IF(D41>=$K$4,"Tier C (Top 70%)","Tier D (Bottom 30%)")))) -> Tier A (Top 15%) | F41: =VLOOKUP(E41,'Bid Tiers (Relative Volume)'!$A$5:$C$9,3,FALSE()) -> 1.9
A42: Wellness (Mind & Sleep) | B42: sleep | C42: Exact | D42: 413 | E42: =IF(D42="","No Data",IF(D42>=$K$2,"Tier A (Top 15%)",IF(D42>=$K$3,"Tier B (Top 40%)",IF(D42>=$K$4,"Tier C (Top 70%)","Tier D (Bottom 30%)")))) -> Tier B (Top 40%) | F42: =VLOOKUP(E42,'Bid Tiers (Relative Volume)'!$A$5:$C$9,3,FALSE()) -> 1
... A52: Women's Health | B52: frauen | C52: Exact | D52: 78 | E52: =IF(D52="","No Data",IF(D52>=$K$2,"Tier A (Top 15%)",IF(D52>=$K$3,"Tier B (Top 40%)",IF(D52>=$K$4,"Tier C (Top 70%)","Tier D (Bottom 30%)")))) -> Tier C (Top 70%) | F52: =VLOOKUP(E52,'Bid Tiers (Relative Volume)'!$A$5:$C$9,3,FALSE()) -> 0.65
A53: Women's Health | B53: cycle | C53: Exact | D53: 79 | E53: =IF(D53="","No Data",IF(D53>=$K$2,"Tier A (Top 15%)",IF(D53>=$K$3,"Tier B (Top 40%)",IF(D53>=$K$4,"Tier C (Top 70%)","Tier D (Bottom 30%)")))) -> Tier C (Top 70%) | F53: =VLOOKUP(E53,'Bid Tiers (Relative Volume)'!$A$5:$C$9,3,FALSE()) -> 0.65 | G53: Ambiguous standalone term — classified as Women's Health (menstrual cycle) since period/menstruation terms appear alongside it in this market; could also mean 'sleep cycle' in some contexts.
A54: Women's Health | B54: women | C54: Exact | D54: 0 | E54: =IF(D54="","No Data",IF(D54>=$K$2,"Tier A (Top 15%)",IF(D54>=$K$3,"Tier B (Top 40%)",IF(D54>=$K$4,"Tier C (Top 70%)","Tier D (Bottom 30%)")))) -> Tier D (Bottom 30%) | F54: =VLOOKUP(E54,'Bid Tiers (Relative Volume)'!$A$5:$C$9,3,FALSE()) -> 0.4
A55: Fasting & Metabolic | B55: fasting | C55: Exact | D55: 443 | E55: =IF(D55="","No Data",IF(D55>=$K$2,"Tier A (Top 15%)",IF(D55>=$K$3,"Tier B (Top 40%)",IF(D55>=$K$4,"Tier C (Top 70%)","Tier D (Bottom 30%)")))) -> Tier B (Top 40%) | F55: =VLOOKUP(E55,'Bid Tiers (Relative Volume)'!$A$5:$C$9,3,FALSE()) -> 1
...

Sheet Netherlands
A1: Bluom — Apple Search Ads — Netherlands | J1: Thresholds (from this tab's own data):
A2: Ranked by Apple's own volume figure, relative to other keywords in this market (see Bid Tiers (Relative Volume)). | J2: P85 | K2: =PERCENTILE(D8:D59,0.85) -> 243.5
A3: Ad Group | B3: Keyword | C3: Match Type | D3: Apple Volume (relative) | E3: Tier | F3: Suggested Max CPT ($) | G3: Notes | J3: P60 | K3: =PERCENTILE(D8:D59,0.6) -> 146
A4: Brand | B4: bluom | C4: Exact | D4: — | E4: Brand | F4: 0.3 | G4: Defensive brand term. | J4: P30 | K4: =PERCENTILE(D8:D59,0.3) -> 2
A5: Brand | B5: bluom app | C5: Exact | D5: — | E5: Brand | F5: 0.3 | G5: Defensive brand term.
A6: Brand | B6: bluom health os | C6: Exact | D6: — | E6: Brand | F6: 0.3 | G6: Defensive brand term — matches your new positioning line.
A7: Discovery | B7: [Search Match ON — no explicit keywords] | C7: Search Match | D7: — | E7: — | F7: 0.4 | G7: Especially useful here — let Apple surface real local search terms this thinner keyword list might be missing.
A8: AI Coach & Scanner | B8: coach | C8: Exact | D8: 205 | E8: =IF(D8="","No Data",IF(D8>=$K$2,"Tier A (Top 15%)",IF(D8>=$K$3,"Tier B (Top 40%)",IF(D8>=$K$4,"Tier C (Top 70%)","Tier D (Bottom 30%)")))) -> Tier B (Top 40%) | F8: =VLOOKUP(E8,'Bid Tiers (Relative Volume)'!$A$5:$C$9,3,FALSE()) -> 1
A9: Fuel (Nutrition) | B9: calorieënteller | C9: Exact | D9: 416 | E9: =IF(D9="","No Data",IF(D9>=$K$2,"Tier A (Top 15%)",IF(D9>=$K$3,"Tier B (Top 40%)",IF(D9>=$K$4,"Tier C (Top 70%)","Tier D (Bottom 30%)")))) -> Tier A (Top 15%) | F9: =VLOOKUP(E9,'Bid Tiers (Relative Volume)'!$A$5:$C$9,3,FALSE()) -> 1.9
A10: Fuel (Nutrition) | B10: macro | C10: Exact | D10: 197 | E10: =IF(D10="","No Data",IF(D10>=$K$2,"Tier A (Top 15%)",IF(D10>=$K$3,"Tier B (Top 40%)",IF(D10>=$K$4,"Tier C (Top 70%)","Tier D (Bottom 30%)")))) -> Tier B (Top 40%) | F10: =VLOOKUP(E10,'Bid Tiers (Relative Volume)'!$A$5:$C$9,3,FALSE()) -> 1
A11: Fuel (Nutrition) | B11: koken | C11: Exact | D11: 157 | E11: =IF(D11="","No Data",IF(D11>=$K$2,"Tier A (Top 15%)",IF(D11>=$K$3,"Tier B (Top 40%)",IF(D11>=$K$4,"Tier C (Top 70%)","Tier D (Bottom 30%)")))) -> Tier B (Top 40%) | F11: =VLOOKUP(E11,'Bid Tiers (Relative Volume)'!$A$5:$C$9,3,FALSE()) -> 1
A12: Fuel (Nutrition) | B12: boodschappenlijstje | C12: Exact | D12: 105 | E12: =IF(D12="","No Data",IF(D12>=$K$2,"Tier A (Top 15%)",IF(D12>=$K$3,"Tier B (Top 40%)",IF(D12>=$K$4,"Tier C (Top 70%)","Tier D (Bottom 30%)")))) -> Tier C (Top 70%) | F12: =VLOOKUP(E12,'Bid Tiers (Relative Volume)'!$A$5:$C$9,3,FALSE()) -> 0.65
A13: Fuel (Nutrition) | B13: calorie | C13: Exact | D13: 304 | E13: =IF(D13="","No Data",IF(D13>=$K$2,"Tier A (Top 15%)",IF(D13>=$K$3,"Tier B (Top 40%)",IF(D13>=$K$4,"Tier C (Top 70%)","Tier D (Bottom 30%)")))) -> Tier A (Top 15%) | F13: =VLOOKUP(E13,'Bid Tiers (Relative Volume)'!$A$5:$C$9,3,FALSE()) -> 1.9
A14: Fuel (Nutrition) | B14: voeding | C14: Exact | D14: 18 | E14: =IF(D14="","No Data",IF(D14>=$K$2,"Tier A (Top 15%)",IF(D14>=$K$3,"Tier B (Top 40%)",IF(D14>=$K$4,"Tier C (Top 70%)","Tier D (Bottom 30%)")))) -> Tier C (Top 70%) | F14: =VLOOKUP(E14,'Bid Tiers (Relative Volume)'!$A$5:$C$9,3,FALSE()) -> 0.65
A15: Fuel (Nutrition) | B15: maaltijd | C15: Exact | D15: 0 | E15: =IF(D15="","No Data",IF(D15>=$K$2,"Tier A (Top 15%)",IF(D15>=$K$3,"Tier B (Top 40%)",IF(D15>=$K$4,"Tier C (Top 70%)","Tier D (Bottom 30%)")))) -> Tier D (Bottom 30%) | F15: =VLOOKUP(E15,'Bid Tiers (Relative Volume)'!$A$5:$C$9,3,FALSE()) -> 0.4
A16: Fuel (Nutrition) | B16: nutrition | C16: Exact | D16: 1 | E16: =IF(D16="","No Data",IF(D16>=$K$2,"Tier A (Top 15%)",IF(D16>=$K$3,"Tier B (Top 40%)",IF(D16>=$K$4,"Tier C (Top 70%)","Tier D (Bottom 30%)")))) -> Tier D (Bottom 30%) | F16: =VLOOKUP(E16,'Bid Tiers (Relative Volume)'!$A$5:$C$9,3,FALSE()) -> 0.4
A17: Fuel (Nutrition) | B17: gewicht | C17: Exact | D17: 2 | E17: =IF(D17="","No Data",IF(D17>=$K$2,"Tier A (Top 15%)",IF(D17>=$K$3,"Tier B (Top 40%)",IF(D17>=$K$4,"Tier C (Top 70%)","Tier D (Bottom 30%)")))) -> Tier C (Top 70%) | F17: =VLOOKUP(E17,'Bid Tiers (Relative Volume)'!$A$5:$C$9,3,FALSE()) -> 0.65
A18: Fuel (Nutrition) | B18: diet | C18: Exact | D18: 2 | E18: =IF(D18="","No Data",IF(D18>=$K$2,"Tier A (Top 15%)",IF(D18>=$K$3,"Tier B (Top 40%)",IF(D18>=$K$4,"Tier C (Top 70%)","Tier D (Bottom 30%)")))) -> Tier C (Top 70%) | F18: =VLOOKUP(E18,'Bid Tiers (Relative Volume)'!$A$5:$C$9,3,FALSE()) -> 0.65
A19: Fuel (Nutrition) | B19: macro tracker | C19: Exact | D19: 1 | E19: =IF(D19="","No Data",IF(D19>=$K$2,"Tier A (Top 15%)",IF(D19>=$K$3,"Tier B (Top 40%)",IF(D19>=$K$4,"Tier C (Top 70%)","Tier D (Bottom 30%)")))) -> Tier D (Bottom 30%) | F19: =VLOOKUP(E19,'Bid Tiers (Relative Volume)'!$A$5:$C$9,3,FALSE()) -> 0.4
... A42: Wellness (Mind & Sleep) | B42: sleep | C42: Exact | D42: 239 | E42: =IF(D42="","No Data",IF(D42>=$K$2,"Tier A (Top 15%)",IF(D42>=$K$3,"Tier B (Top 40%)",IF(D42>=$K$4,"Tier C (Top 70%)","Tier D (Bottom 30%)")))) -> Tier B (Top 40%) | F42: =VLOOKUP(E42,'Bid Tiers (Relative Volume)'!$A$5:$C$9,3,FALSE()) -> 1
A43: Wellness (Mind & Sleep) | B43: sleep recorder | C43: Exact | E43: =IF(D43="","No Data",IF(D43>=$K$2,"Tier A (Top 15%)",IF(D43>=$K$3,"Tier B (Top 40%)",IF(D43>=$K$4,"Tier C (Top 70%)","Tier D (Bottom 30%)")))) -> No Data | F43: =VLOOKUP(E43,'Bid Tiers (Relative Volume)'!$A$5:$C$9,3,FALSE()) -> 0.2
A44: Wellness (Mind & Sleep) | B44: focus | C44: Exact | D44: 223 | E44: =IF(D44="","No Data",IF(D44>=$K$2,"Tier A (Top 15%)",IF(D44>=$K$3,"Tier B (Top 40%)",IF(D44>=$K$4,"Tier C (Top 70%)","Tier D (Bottom 30%)")))) -> Tier B (Top 40%) | F44: =VLOOKUP(E44,'Bid Tiers (Relative Volume)'!$A$5:$C$9,3,FALSE()) -> 1
A45: Wellness (Mind & Sleep) | B45: water | C45: Exact | D45: 213 | E45: =IF(D45="","No Data",IF(D45>=$K$2,"Tier A (Top 15%)",IF(D45>=$K$3,"Tier B (Top 40%)",IF(D45>=$K$4,"Tier C (Top 70%)","Tier D (Bottom 30%)")))) -> Tier B (Top 40%) | F45: =VLOOKUP(E45,'Bid Tiers (Relative Volume)'!$A$5:$C$9,3,FALSE()) -> 1
A46: Wellness (Mind & Sleep) | B46: brain | C46: Exact | D46: 219 | E46: =IF(D46="","No Data",IF(D46>=$K$2,"Tier A (Top 15%)",IF(D46>=$K$3,"Tier B (Top 40%)",IF(D46>=$K$4,"Tier C (Top 70%)","Tier D (Bottom 30%)")))) -> Tier B (Top 40%) | F46: =VLOOKUP(E46,'Bid Tiers (Relative Volume)'!$A$5:$C$9,3,FALSE()) -> 1
A47: Wellness (Mind & Sleep) | B47: meditation | C47: Exact | D47: 223 | E47: =IF(D47="","No Data",IF(D47>=$K$2,"Tier A (Top 15%)",IF(D47>=$K$3,"Tier B (Top 40%)",IF(D47>=$K$4,"Tier C (Top 70%)","Tier D (Bottom 30%)")))) -> Tier B (Top 40%) | F47: =VLOOKUP(E47,'Bid Tiers (Relative Volume)'!$A$5:$C$9,3,FALSE()) -> 1
A48: Wellness (Mind & Sleep) | B48: mood | C48: Exact | D48: 123 | E48: =IF(D48="","No Data",IF(D48>=$K$2,"Tier A (Top 15%)",IF(D48>=$K$3,"Tier B (Top 40%)",IF(D48>=$K$4,"Tier C (Top 70%)","Tier D (Bottom 30%)")))) -> Tier C (Top 70%) | F48: =VLOOKUP(E48,'Bid Tiers (Relative Volume)'!$A$5:$C$9,3,FALSE()) -> 0.65
A49: Wellness (Mind & Sleep) | B49: meditatie | C49: Exact | D49: 34 | E49: =IF(D49="","No Data",IF(D49>=$K$2,"Tier A (Top 15%)",IF(D49>=$K$3,"Tier B (Top 40%)",IF(D49>=$K$4,"Tier C (Top 70%)","Tier D (Bottom 30%)")))) -> Tier C (Top 70%) | F49: =VLOOKUP(E49,'Bid Tiers (Relative Volume)'!$A$5:$C$9,3,FALSE()) -> 0.65
A50: Wellness (Mind & Sleep) | B50: brain games | C50: Exact | D50: 5 | E50: =IF(D50="","No Data",IF(D50>=$K$2,"Tier A (Top 15%)",IF(D50>=$K$3,"Tier B (Top 40%)",IF(D50>=$K$4,"Tier C (Top 70%)","Tier D (Bottom 30%)")))) -> Tier C (Top 70%) | F50: =VLOOKUP(E50,'Bid Tiers (Relative Volume)'!$A$5:$C$9,3,FALSE()) -> 0.65
A51: Wellness (Mind & Sleep) | B51: stemming | C51: Exact | D51: 2 | E51: =IF(D51="","No Data",IF(D51>=$K$2,"Tier A (Top 15%)",IF(D51>=$K$3,"Tier B (Top 40%)",IF(D51>=$K$4,"Tier C (Top 70%)","Tier D (Bottom 30%)")))) -> Tier C (Top 70%) | F51: =VLOOKUP(E51,'Bid Tiers (Relative Volume)'!$A$5:$C$9,3,FALSE()) -> 0.65
A52: Women's Health | B52: menstruatie | C52: Exact | D52: 146 | E52: =IF(D52="","No Data",IF(D52>=$K$2,"Tier A (Top 15%)",IF(D52>=$K$3,"Tier B (Top 40%)",IF(D52>=$K$4,"Tier C (Top 70%)","Tier D (Bottom 30%)")))) -> Tier B (Top 40%) | F52: =VLOOKUP(E52,'Bid Tiers (Relative Volume)'!$A$5:$C$9,3,FALSE()) -> 1
A53: Women's Health | B53: cycle | C53: Exact | D53: 13 | E53: =IF(D53="","No Data",IF(D53>=$K$2,"Tier A (Top 15%)",IF(D53>=$K$3,"Tier B (Top 40%)",IF(D53>=$K$4,"Tier C (Top 70%)","Tier D (Bottom 30%)")))) -> Tier C (Top 70%) | F53: =VLOOKUP(E53,'Bid Tiers (Relative Volume)'!$A$5:$C$9,3,FALSE()) -> 0.65 | G53: Ambiguous standalone term — classified as Women's Health (menstrual cycle) since period/menstruation terms appear alongside it in this market; could also mean 'sleep cycle' in some contexts.
A54: Women's Health | B54: women | C54: Exact | D54: 0 | E54: =IF(D54="","No Data",IF(D54>=$K$2,"Tier A (Top 15%)",IF(D54>=$K$3,"Tier B (Top 40%)",IF(D54>=$K$4,"Tier C (Top 70%)","Tier D (Bottom 30%)")))) -> Tier D (Bottom 30%) | F54: =VLOOKUP(E54,'Bid Tiers (Relative Volume)'!$A$5:$C$9,3,FALSE()) -> 0.4
A55: Women's Health | B55: periode | C55: Exact | D55: 0 | E55: =IF(D55="","No Data",IF(D55>=$K$2,"Tier A (Top 15%)",IF(D55>=$K$3,"Tier B (Top 40%)",IF(D55>=$K$4,"Tier C (Top 70%)","Tier D (Bottom 30%)")))) -> Tier D (Bottom 30%) | F55: =VLOOKUP(E55,'Bid Tiers (Relative Volume)'!$A$5:$C$9,3,FALSE()) -> 0.4
A56: Fasting & Metabolic | B56: fasting | C56: Exact | D56: 176 | E56: =IF(D56="","No Data",IF(D56>=$K$2,"Tier A (Top 15%)",IF(D56>=$K$3,"Tier B (Top 40%)",IF(D56>=$K$4,"Tier C (Top 70%)","Tier D (Bottom 30%)")))) -> Tier B (Top 40%) | F56: =VLOOKUP(E56,'Bid Tiers (Relative Volume)'!$A$5:$C$9,3,FALSE()) -> 1
A57: Fasting & Metabolic | B57: vasten | C57: Exact | D57: 2 | E57: =IF(D57="","No Data",IF(D57>=$K$2,"Tier A (Top 15%)",IF(D57>=$K$3,"Tier B (Top 40%)",IF(D57>=$K$4,"Tier C (Top 70%)","Tier D (Bottom 30%)")))) -> Tier C (Top 70%) | F57: =VLOOKUP(E57,'Bid Tiers (Relative Volume)'!$A$5:$C$9,3,FALSE()) -> 0.65
A58: Tools (Calculators) | B58: bmi calculator | C58: Exact | D58: 146 | E58: =IF(D58="","No Data",IF(D58>=$K$2,"Tier A (Top 15%)",IF(D58>=$K$3,"Tier B (Top 40%)",IF(D58>=$K$4,"Tier C (Top 70%)","Tier D (Bottom 30%)")))) -> Tier B (Top 40%) | F58: =VLOOKUP(E58,'Bid Tiers (Relative Volume)'!$A$5:$C$9,3,FALSE()) -> 1
A59: Tools (Calculators) | B59: bmi | C59: Exact | D59: 105 | E59: =IF(D59="","No Data",IF(D59>=$K$2,"Tier A (Top 15%)",IF(D59>=$K$3,"Tier B (Top 40%)",IF(D59>=$K$4,"Tier C (Top 70%)","Tier D (Bottom 30%)")))) -> Tier C (Top 70%) | F59: =VLOOKUP(E59,'Bid Tiers (Relative Volume)'!$A$5:$C$9,3,FALSE()) -> 0.65

Sheet Spain
A1: Bluom — Apple Search Ads — Spain | J1: Thresholds (from this tab's own data):
A2: No Apple-specific data for this market — ranked by combined Google/Semrush search volume, relative to other keywords in this market (see Bid Tiers (Relative Volume)). | J2: P85 | K2: =PERCENTILE(D8:D39,0.85) -> 10670
A3: Ad Group | B3: Keyword | C3: Match Type | D3: Search Volume (relative) | E3: Tier | F3: Suggested Max CPT ($) | G3: Notes | J3: P60 | K3: =PERCENTILE(D8:D39,0.6) -> 1780
A4: Brand | B4: bluom | C4: Exact | D4: — | E4: Brand | F4: 0.3 | G4: Defensive brand term. | J4: P30 | K4: =PERCENTILE(D8:D39,0.3) -> 20
A5: Brand | B5: bluom app | C5: Exact | D5: — | E5: Brand | F5: 0.3 | G5: Defensive brand term.
A6: Brand | B6: bluom health os | C6: Exact | D6: — | E6: Brand | F6: 0.3 | G6: Defensive brand term — matches your new positioning line.
A7: Discovery | B7: [Search Match ON — no explicit keywords] | C7: Search Match | D7: — | E7: — | F7: 0.4 | G7: Especially useful here — let Apple surface real local search terms this thinner keyword list might be missing.
A8: AI Coach & Scanner | B8: entrenador | C8: Exact | D8: 9900 | E8: =IF(D8="","No Data",IF(D8>=$K$2,"Tier A (Top 15%)",IF(D8>=$K$3,"Tier B (Top 40%)",IF(D8>=$K$4,"Tier C (Top 70%)","Tier D (Bottom 30%)")))) -> Tier B (Top 40%) | F8: =VLOOKUP(E8,'Bid Tiers (Relative Volume)'!$A$5:$C$9,3,FALSE()) -> 1
A9: AI Coach & Scanner | B9: coaching | C9: Exact | D9: 8100 | E9: =IF(D9="","No Data",IF(D9>=$K$2,"Tier A (Top 15%)",IF(D9>=$K$3,"Tier B (Top 40%)",IF(D9>=$K$4,"Tier C (Top 70%)","Tier D (Bottom 30%)")))) -> Tier B (Top 40%) | F9: =VLOOKUP(E9,'Bid Tiers (Relative Volume)'!$A$5:$C$9,3,FALSE()) -> 1
A10: Fuel (Nutrition) | B10: macro | C10: Exact | D10: 14800 | E10: =IF(D10="","No Data",IF(D10>=$K$2,"Tier A (Top 15%)",IF(D10>=$K$3,"Tier B (Top 40%)",IF(D10>=$K$4,"Tier C (Top 70%)","Tier D (Bottom 30%)")))) -> Tier A (Top 15%) | F10: =VLOOKUP(E10,'Bid Tiers (Relative Volume)'!$A$5:$C$9,3,FALSE()) -> 1.9
A11: Fuel (Nutrition) | B11: dieta | C11: Exact | D11: 6600 | E11: =IF(D11="","No Data",IF(D11>=$K$2,"Tier A (Top 15%)",IF(D11>=$K$3,"Tier B (Top 40%)",IF(D11>=$K$4,"Tier C (Top 70%)","Tier D (Bottom 30%)")))) -> Tier B (Top 40%) | F11: =VLOOKUP(E11,'Bid Tiers (Relative Volume)'!$A$5:$C$9,3,FALSE()) -> 1
A12: Fuel (Nutrition) | B12: peso | C12: Exact | D12: 4400 | E12: =IF(D12="","No Data",IF(D12>=$K$2,"Tier A (Top 15%)",IF(D12>=$K$3,"Tier B (Top 40%)",IF(D12>=$K$4,"Tier C (Top 70%)","Tier D (Bottom 30%)")))) -> Tier B (Top 40%) | F12: =VLOOKUP(E12,'Bid Tiers (Relative Volume)'!$A$5:$C$9,3,FALSE()) -> 1
A13: Fuel (Nutrition) | B13: calorías | C13: Exact | D13: 2900 | E13: =IF(D13="","No Data",IF(D13>=$K$2,"Tier A (Top 15%)",IF(D13>=$K$3,"Tier B (Top 40%)",IF(D13>=$K$4,"Tier C (Top 70%)","Tier D (Bottom 30%)")))) -> Tier B (Top 40%) | F13: =VLOOKUP(E13,'Bid Tiers (Relative Volume)'!$A$5:$C$9,3,FALSE()) -> 1
A14: Fuel (Nutrition) | B14: contador de calorías | C14: Exact | D14: 1300 | E14: =IF(D14="","No Data",IF(D14>=$K$2,"Tier A (Top 15%)",IF(D14>=$K$3,"Tier B (Top 40%)",IF(D14>=$K$4,"Tier C (Top 70%)","Tier D (Bottom 30%)")))) -> Tier C (Top 70%) | F14: =VLOOKUP(E14,'Bid Tiers (Relative Volume)'!$A$5:$C$9,3,FALSE()) -> 0.65
A15: Fuel (Nutrition) | B15: caloría | C15: Exact | D15: 1000 | E15: =IF(D15="","No Data",IF(D15>=$K$2,"Tier A (Top 15%)",IF(D15>=$K$3,"Tier B (Top 40%)",IF(D15>=$K$4,"Tier C (Top 70%)","Tier D (Bottom 30%)")))) -> Tier C (Top 70%) | F15: =VLOOKUP(E15,'Bid Tiers (Relative Volume)'!$A$5:$C$9,3,FALSE()) -> 0.65
A16: Fuel (Nutrition) | B16: lista de compras | C16: Exact | D16: 880 | E16: =IF(D16="","No Data",IF(D16>=$K$2,"Tier A (Top 15%)",IF(D16>=$K$3,"Tier B (Top 40%)",IF(D16>=$K$4,"Tier C (Top 70%)","Tier D (Bottom 30%)")))) -> Tier C (Top 70%) | F16: =VLOOKUP(E16,'Bid Tiers (Relative Volume)'!$A$5:$C$9,3,FALSE()) -> 0.65
A17: Fuel (Nutrition) | B17: seguimiento de peso | C17: Exact | D17: 20 | E17: =IF(D17="","No Data",IF(D17>=$K$2,"Tier A (Top 15%)",IF(D17>=$K$3,"Tier B (Top 40%)",IF(D17>=$K$4,"Tier C (Top 70%)","Tier D (Bottom 30%)")))) -> Tier C (Top 70%) | F17: =VLOOKUP(E17,'Bid Tiers (Relative Volume)'!$A$5:$C$9,3,FALSE()) -> 0.65
A18: Fuel (Nutrition) | B18: seguimiento de macros | C18: Exact | D18: 0 | E18: =IF(D18="","No Data",IF(D18>=$K$2,"Tier A (Top 15%)",IF(D18>=$K$3,"Tier B (Top 40%)",IF(D18>=$K$4,"Tier C (Top 70%)","Tier D (Bottom 30%)")))) -> Tier D (Bottom 30%) | F18: =VLOOKUP(E18,'Bid Tiers (Relative Volume)'!$A$5:$C$9,3,FALSE()) -> 0.4
A19: Move (Fitness) | B19: fitness | C19: Exact | D19: 18100 | E19: =IF(D19="","No Data",IF(D19>=$K$2,"Tier A (Top 15%)",IF(D19>=$K$3,"Tier B (Top 40%)",IF(D19>=$K$4,"Tier C (Top 70%)","Tier D (Bottom 30%)")))) -> Tier A (Top 15%) | F19: =VLOOKUP(E19,'Bid Tiers (Relative Volume)'!$A$5:$C$9,3,FALSE()) -> 1.9
... A39: Women's Health | B39: seguimiento del periodo | C39: Exact | D39: 0 | E39: =IF(D39="","No Data",IF(D39>=$K$2,"Tier A (Top 15%)",IF(D39>=$K$3,"Tier B (Top 40%)",IF(D39>=$K$4,"Tier C (Top 70%)","Tier D (Bottom 30%)")))) -> Tier D (Bottom 30%) | F39: =VLOOKUP(E39,'Bid Tiers (Relative Volume)'!$A$5:$C$9,3,FALSE()) -> 0.4

Sheet France
A1: Bluom — Apple Search Ads — France | J1: Thresholds (from this tab's own data):
A2: No Apple-specific data for this market — ranked by combined Google/Semrush search volume, relative to other keywords in this market (see Bid Tiers (Relative Volume)). | J2: P85 | K2: =PERCENTILE(D8:D39,0.85) -> 14200
A3: Ad Group | B3: Keyword | C3: Match Type | D3: Search Volume (relative) | E3: Tier | F3: Suggested Max CPT ($) | G3: Notes | J3: P60 | K3: =PERCENTILE(D8:D39,0.6) -> 7020
A4: Brand | B4: bluom | C4: Exact | D4: — | E4: Brand | F4: 0.3 | G4: Defensive brand term. | J4: P30 | K4: =PERCENTILE(D8:D39,0.3) -> 119
A5: Brand | B5: bluom app | C5: Exact | D5: — | E5: Brand | F5: 0.3 | G5: Defensive brand term.
A6: Brand | B6: bluom health os | C6: Exact | D6: — | E6: Brand | F6: 0.3 | G6: Defensive brand term — matches your new positioning line.
A7: Discovery | B7: [Search Match ON — no explicit keywords] | C7: Search Match | D7: — | E7: — | F7: 0.4 | G7: Especially useful here — let Apple surface real local search terms this thinner keyword list might be missing.
A8: AI Coach & Scanner | B8: coach | C8: Exact | D8: 135000 | E8: =IF(D8="","No Data",IF(D8>=$K$2,"Tier A (Top 15%)",IF(D8>=$K$3,"Tier B (Top 40%)",IF(D8>=$K$4,"Tier C (Top 70%)","Tier D (Bottom 30%)")))) -> Tier A (Top 15%) | F8: =VLOOKUP(E8,'Bid Tiers (Relative Volume)'!$A$5:$C$9,3,FALSE()) -> 1.9
A9: AI Coach & Scanner | B9: coaching | C9: Exact | D9: 8100 | E9: =IF(D9="","No Data",IF(D9>=$K$2,"Tier A (Top 15%)",IF(D9>=$K$3,"Tier B (Top 40%)",IF(D9>=$K$4,"Tier C (Top 70%)","Tier D (Bottom 30%)")))) -> Tier B (Top 40%) | F9: =VLOOKUP(E9,'Bid Tiers (Relative Volume)'!$A$5:$C$9,3,FALSE()) -> 1
A10: Fuel (Nutrition) | B10: poids | C10: Exact | D10: 12100 | E10: =IF(D10="","No Data",IF(D10>=$K$2,"Tier A (Top 15%)",IF(D10>=$K$3,"Tier B (Top 40%)",IF(D10>=$K$4,"Tier C (Top 70%)","Tier D (Bottom 30%)")))) -> Tier B (Top 40%) | F10: =VLOOKUP(E10,'Bid Tiers (Relative Volume)'!$A$5:$C$9,3,FALSE()) -> 1
A11: Fuel (Nutrition) | B11: macro | C11: Exact | D11: 9900 | E11: =IF(D11="","No Data",IF(D11>=$K$2,"Tier A (Top 15%)",IF(D11>=$K$3,"Tier B (Top 40%)",IF(D11>=$K$4,"Tier C (Top 70%)","Tier D (Bottom 30%)")))) -> Tier B (Top 40%) | F11: =VLOOKUP(E11,'Bid Tiers (Relative Volume)'!$A$5:$C$9,3,FALSE()) -> 1
A12: Fuel (Nutrition) | B12: liste de courses | C12: Exact | D12: 9900 | E12: =IF(D12="","No Data",IF(D12>=$K$2,"Tier A (Top 15%)",IF(D12>=$K$3,"Tier B (Top 40%)",IF(D12>=$K$4,"Tier C (Top 70%)","Tier D (Bottom 30%)")))) -> Tier B (Top 40%) | F12: =VLOOKUP(E12,'Bid Tiers (Relative Volume)'!$A$5:$C$9,3,FALSE()) -> 1
A13: Fuel (Nutrition) | B13: régime | C13: Exact | D13: 8100 | E13: =IF(D13="","No Data",IF(D13>=$K$2,"Tier A (Top 15%)",IF(D13>=$K$3,"Tier B (Top 40%)",IF(D13>=$K$4,"Tier C (Top 70%)","Tier D (Bottom 30%)")))) -> Tier B (Top 40%) | F13: =VLOOKUP(E13,'Bid Tiers (Relative Volume)'!$A$5:$C$9,3,FALSE()) -> 1
A14: Fuel (Nutrition) | B14: calorie | C14: Exact | D14: 5400 | E14: =IF(D14="","No Data",IF(D14>=$K$2,"Tier A (Top 15%)",IF(D14>=$K$3,"Tier B (Top 40%)",IF(D14>=$K$4,"Tier C (Top 70%)","Tier D (Bottom 30%)")))) -> Tier C (Top 70%) | F14: =VLOOKUP(E14,'Bid Tiers (Relative Volume)'!$A$5:$C$9,3,FALSE()) -> 0.65
A15: Fuel (Nutrition) | B15: calories | C15: Exact | D15: 4400 | E15: =IF(D15="","No Data",IF(D15>=$K$2,"Tier A (Top 15%)",IF(D15>=$K$3,"Tier B (Top 40%)",IF(D15>=$K$4,"Tier C (Top 70%)","Tier D (Bottom 30%)")))) -> Tier C (Top 70%) | F15: =VLOOKUP(E15,'Bid Tiers (Relative Volume)'!$A$5:$C$9,3,FALSE()) -> 0.65
A16: Fuel (Nutrition) | B16: compteur de calories | C16: Exact | D16: 1000 | E16: =IF(D16="","No Data",IF(D16>=$K$2,"Tier A (Top 15%)",IF(D16>=$K$3,"Tier B (Top 40%)",IF(D16>=$K$4,"Tier C (Top 70%)","Tier D (Bottom 30%)")))) -> Tier C (Top 70%) | F16: =VLOOKUP(E16,'Bid Tiers (Relative Volume)'!$A$5:$C$9,3,FALSE()) -> 0.65
A17: Fuel (Nutrition) | B17: suivi du poids | C17: Exact | D17: 140 | E17: =IF(D17="","No Data",IF(D17>=$K$2,"Tier A (Top 15%)",IF(D17>=$K$3,"Tier B (Top 40%)",IF(D17>=$K$4,"Tier C (Top 70%)","Tier D (Bottom 30%)")))) -> Tier C (Top 70%) | F17: =VLOOKUP(E17,'Bid Tiers (Relative Volume)'!$A$5:$C$9,3,FALSE()) -> 0.65
A18: Fuel (Nutrition) | B18: suivi des macros | C18: Exact | D18: 20 | E18: =IF(D18="","No Data",IF(D18>=$K$2,"Tier A (Top 15%)",IF(D18>=$K$3,"Tier B (Top 40%)",IF(D18>=$K$4,"Tier C (Top 70%)","Tier D (Bottom 30%)")))) -> Tier D (Bottom 30%) | F18: =VLOOKUP(E18,'Bid Tiers (Relative Volume)'!$A$5:$C$9,3,FALSE()) -> 0.4
A19: Move (Fitness) | B19: sport | C19: Exact | D19: 165000 | E19: =IF(D19="","No Data",IF(D19>=$K$2,"Tier A (Top 15%)",IF(D19>=$K$3,"Tier B (Top 40%)",IF(D19>=$K$4,"Tier C (Top 70%)","Tier D (Bottom 30%)")))) -> Tier A (Top 15%) | F19: =VLOOKUP(E19,'Bid Tiers (Relative Volume)'!$A$5:$C$9,3,FALSE()) -> 1.9
... A39: Women's Health | B39: suivi des règles | C39: Exact | D39: 70 | E39: =IF(D39="","No Data",IF(D39>=$K$2,"Tier A (Top 15%)",IF(D39>=$K$3,"Tier B (Top 40%)",IF(D39>=$K$4,"Tier C (Top 70%)","Tier D (Bottom 30%)")))) -> Tier D (Bottom 30%) | F39: =VLOOKUP(E39,'Bid Tiers (Relative Volume)'!$A$5:$C$9,3,FALSE()) -> 0.4

Sheet Austria
A1: Bluom — Apple Search Ads — Austria
A2: Ranked by Apple's 0-100 popularity score (same method as USA/UK/Canada).
A3: Ad Group | B3: Keyword | C3: Match Type | D3: Popularity Score | E3: Tier | F3: Suggested Max CPT ($) | G3: Notes
A4: Brand | B4: bluom | C4: Exact | D4: — | E4: Brand | F4: 0.3 | G4: Defensive brand term.
A5: Brand | B5: bluom app | C5: Exact | D5: — | E5: Brand | F5: 0.3 | G5: Defensive brand term.
A6: Brand | B6: bluom health os | C6: Exact | D6: — | E6: Brand | F6: 0.3 | G6: Defensive brand term — matches your new positioning line.
A7: Discovery | B7: [Search Match ON — no explicit keywords] | C7: Search Match | D7: — | E7: — | F7: 0.4 | G7: Especially useful here — let Apple surface real local search terms this thinner keyword list might be missing.
A8: Fuel (Nutrition) | B8: kalorienzähler | C8: Exact | D8: 5 | E8: =IF(D8="","No Data",INDEX('Bid Tiers (Popularity Score)'!$A$4:$A$7,MATCH(D8,'Bid Tiers (Popularity Score)'!$B$4:$B$7,1))) -> Tier D — Below Threshold (<5) | F8: =IF(D8="",0.25,INDEX('Bid Tiers (Popularity Score)'!$E$4:$E$7,MATCH(D8,'Bid Tiers (Popularity Score)'!$B$4:$B$7,1))) -> 0.5
A9: Fuel (Nutrition) | B9: kalorienzähler gratis | C9: Exact | D9: 5 | E9: =IF(D9="","No Data",INDEX('Bid Tiers (Popularity Score)'!$A$4:$A$7,MATCH(D9,'Bid Tiers (Popularity Score)'!$B$4:$B$7,1))) -> Tier D — Below Threshold (<5) | F9: =IF(D9="",0.25,INDEX('Bid Tiers (Popularity Score)'!$E$4:$E$7,MATCH(D9,'Bid Tiers (Popularity Score)'!$B$4:$B$7,1))) -> 0.5
A10: Fuel (Nutrition) | B10: Kochen | C10: Exact | D10: 36 | E10: =IF(D10="","No Data",INDEX('Bid Tiers (Popularity Score)'!$A$4:$A$7,MATCH(D10,'Bid Tiers (Popularity Score)'!$B$4:$B$7,1))) -> Tier B — Mid Volume | F10: =IF(D10="",0.25,INDEX('Bid Tiers (Popularity Score)'!$E$4:$E$7,MATCH(D10,'Bid Tiers (Popularity Score)'!$B$4:$B$7,1))) -> 1.25
A11: Fuel (Nutrition) | B11: gewichtskontrolle | C11: Exact | D11: 25 | E11: =IF(D11="","No Data",INDEX('Bid Tiers (Popularity Score)'!$A$4:$A$7,MATCH(D11,'Bid Tiers (Popularity Score)'!$B$4:$B$7,1))) -> Tier B — Mid Volume | F11: =IF(D11="",0.25,INDEX('Bid Tiers (Popularity Score)'!$E$4:$E$7,MATCH(D11,'Bid Tiers (Popularity Score)'!$B$4:$B$7,1))) -> 1.25
A12: Fuel (Nutrition) | B12: gewicht | C12: Exact | D12: 21 | E12: =IF(D12="","No Data",INDEX('Bid Tiers (Popularity Score)'!$A$4:$A$7,MATCH(D12,'Bid Tiers (Popularity Score)'!$B$4:$B$7,1))) -> Tier B — Mid Volume | F12: =IF(D12="",0.25,INDEX('Bid Tiers (Popularity Score)'!$E$4:$E$7,MATCH(D12,'Bid Tiers (Popularity Score)'!$B$4:$B$7,1))) -> 1.25
A13: Fuel (Nutrition) | B13: diät | C13: Exact | D13: 13 | E13: =IF(D13="","No Data",INDEX('Bid Tiers (Popularity Score)'!$A$4:$A$7,MATCH(D13,'Bid Tiers (Popularity Score)'!$B$4:$B$7,1))) -> Tier C — Long-Tail | F13: =IF(D13="",0.25,INDEX('Bid Tiers (Popularity Score)'!$E$4:$E$7,MATCH(D13,'Bid Tiers (Popularity Score)'!$B$4:$B$7,1))) -> 0.75
A14: Fuel (Nutrition) | B14: makro | C14: Exact | D14: 7 | E14: =IF(D14="","No Data",INDEX('Bid Tiers (Popularity Score)'!$A$4:$A$7,MATCH(D14,'Bid Tiers (Popularity Score)'!$B$4:$B$7,1))) -> Tier C — Long-Tail | F14: =IF(D14="",0.25,INDEX('Bid Tiers (Popularity Score)'!$E$4:$E$7,MATCH(D14,'Bid Tiers (Popularity Score)'!$B$4:$B$7,1))) -> 0.75
A15: Fuel (Nutrition) | B15: nutrition | C15: Exact | E15: =IF(D15="","No Data",INDEX('Bid Tiers (Popularity Score)'!$A$4:$A$7,MATCH(D15,'Bid Tiers (Popularity Score)'!$B$4:$B$7,1))) -> No Data | F15: =IF(D15="",0.25,INDEX('Bid Tiers (Popularity Score)'!$E$4:$E$7,MATCH(D15,'Bid Tiers (Popularity Score)'!$B$4:$B$7,1))) -> 0.25
A16: Fuel (Nutrition) | B16: weight tracker | C16: Exact | D16: 7 | E16: =IF(D16="","No Data",INDEX('Bid Tiers (Popularity Score)'!$A$4:$A$7,MATCH(D16,'Bid Tiers (Popularity Score)'!$B$4:$B$7,1))) -> Tier C — Long-Tail | F16: =IF(D16="",0.25,INDEX('Bid Tiers (Popularity Score)'!$E$4:$E$7,MATCH(D16,'Bid Tiers (Popularity Score)'!$B$4:$B$7,1))) -> 0.75
A17: Fuel (Nutrition) | B17: weight loss | C17: Exact | D17: 6 | E17: =IF(D17="","No Data",INDEX('Bid Tiers (Popularity Score)'!$A$4:$A$7,MATCH(D17,'Bid Tiers (Popularity Score)'!$B$4:$B$7,1))) -> Tier C — Long-Tail | F17: =IF(D17="",0.25,INDEX('Bid Tiers (Popularity Score)'!$E$4:$E$7,MATCH(D17,'Bid Tiers (Popularity Score)'!$B$4:$B$7,1))) -> 0.75
A18: Fuel (Nutrition) | B18: weight | C18: Exact | D18: 5 | E18: =IF(D18="","No Data",INDEX('Bid Tiers (Popularity Score)'!$A$4:$A$7,MATCH(D18,'Bid Tiers (Popularity Score)'!$B$4:$B$7,1))) -> Tier D — Below Threshold (<5) | F18: =IF(D18="",0.25,INDEX('Bid Tiers (Popularity Score)'!$E$4:$E$7,MATCH(D18,'Bid Tiers (Popularity Score)'!$B$4:$B$7,1))) -> 0.5
A19: Fuel (Nutrition) | B19: macro | C19: Exact | D19: 5 | E19: =IF(D19="","No Data",INDEX('Bid Tiers (Popularity Score)'!$A$4:$A$7,MATCH(D19,'Bid Tiers (Popularity Score)'!$B$4:$B$7,1))) -> Tier D — Below Threshold (<5) | F19: =IF(D19="",0.25,INDEX('Bid Tiers (Popularity Score)'!$E$4:$E$7,MATCH(D19,'Bid Tiers (Popularity Score)'!$B$4:$B$7,1))) -> 0.5
A20: Fuel (Nutrition) | B20: ernährung | C20: Exact | D20: 5 | E20: =IF(D20="","No Data",INDEX('Bid Tiers (Popularity Score)'!$A$4:$A$7,MATCH(D20,'Bid Tiers (Popularity Score)'!$B$4:$B$7,1))) -> Tier D — Below Threshold (<5) | F20: =IF(D20="",0.25,INDEX('Bid Tiers (Popularity Score)'!$E$4:$E$7,MATCH(D20,'Bid Tiers (Popularity Score)'!$B$4:$B$7,1))) -> 0.5
A21: Fuel (Nutrition) | B21: diet | C21: Exact | D21: 5 | E21: =IF(D21="","No Data",INDEX('Bid Tiers (Popularity Score)'!$A$4:$A$7,MATCH(D21,'Bid Tiers (Popularity Score)'!$B$4:$B$7,1))) -> Tier D — Below Threshold (<5) | F21: =IF(D21="",0.25,INDEX('Bid Tiers (Popularity Score)'!$E$4:$E$7,MATCH(D21,'Bid Tiers (Popularity Score)'!$B$4:$B$7,1))) -> 0.5
A22: Fuel (Nutrition) | B22: macros | C22: Exact | D22: 5 | E22: =IF(D22="","No Data",INDEX('Bid Tiers (Popularity Score)'!$A$4:$A$7,MATCH(D22,'Bid Tiers (Popularity Score)'!$B$4:$B$7,1))) -> Tier D — Below Threshold (<5) | F22: =IF(D22="",0.25,INDEX('Bid Tiers (Popularity Score)'!$E$4:$E$7,MATCH(D22,'Bid Tiers (Popularity Score)'!$B$4:$B$7,1))) -> 0.5
A23: Fuel (Nutrition) | B23: macro tracker | C23: Exact | D23: 5 | E23: =IF(D23="","No Data",INDEX('Bid Tiers (Popularity Score)'!$A$4:$A$7,MATCH(D23,'Bid Tiers (Popularity Score)'!$B$4:$B$7,1))) -> Tier D — Below Threshold (<5) | F23: =IF(D23="",0.25,INDEX('Bid Tiers (Popularity Score)'!$E$4:$E$7,MATCH(D23,'Bid Tiers (Popularity Score)'!$B$4:$B$7,1))) -> 0.5
A24: Fuel (Nutrition) | B24: kalorien | C24: Exact | D24: 5 | E24: =IF(D24="","No Data",INDEX('Bid Tiers (Popularity Score)'!$A$4:$A$7,MATCH(D24,'Bid Tiers (Popularity Score)'!$B$4:$B$7,1))) -> Tier D — Below Threshold (<5) | F24: =IF(D24="",0.25,INDEX('Bid Tiers (Popularity Score)'!$E$4:$E$7,MATCH(D24,'Bid Tiers (Popularity Score)'!$B$4:$B$7,1))) -> 0.5
A25: Fuel (Nutrition) | B25: Kalorientracker | C25: Exact | E25: =IF(D25="","No Data",INDEX('Bid Tiers (Popularity Score)'!$A$4:$A$7,MATCH(D25,'Bid Tiers (Popularity Score)'!$B$4:$B$7,1))) -> No Data | F25: =IF(D25="",0.25,INDEX('Bid Tiers (Popularity Score)'!$E$4:$E$7,MATCH(D25,'Bid Tiers (Popularity Score)'!$B$4:$B$7,1))) -> 0.25
A26: Fuel (Nutrition) | B26: makro tracker | C26: Exact | D26: 0 | E26: =IF(D26="","No Data",INDEX('Bid Tiers (Popularity Score)'!$A$4:$A$7,MATCH(D26,'Bid Tiers (Popularity Score)'!$B$4:$B$7,1))) -> Tier D — Below Threshold (<5) | F26: =IF(D26="",0.25,INDEX('Bid Tiers (Popularity Score)'!$E$4:$E$7,MATCH(D26,'Bid Tiers (Popularity Score)'!$B$4:$B$7,1))) -> 0.5
A27: Move (Fitness) | B27: sport | C27: Exact | D27: 41 | E27: =IF(D27="","No Data",INDEX('Bid Tiers (Popularity Score)'!$A$4:$A$7,MATCH(D27,'Bid Tiers (Popularity Score)'!$B$4:$B$7,1))) -> Tier B — Mid Volume | F27: =IF(D27="",0.25,INDEX('Bid Tiers (Popularity Score)'!$E$4:$E$7,MATCH(D27,'Bid Tiers (Popularity Score)'!$B$4:$B$7,1))) -> 1.25
A28: Move (Fitness) | B28: trainingsplan | C28: Exact | D28: 39 | E28: =IF(D28="","No Data",INDEX('Bid Tiers (Popularity Score)'!$A$4:$A$7,MATCH(D28,'Bid Tiers (Popularity Score)'!$B$4:$B$7,1))) -> Tier B — Mid Volume | F28: =IF(D28="",0.25,INDEX('Bid Tiers (Popularity Score)'!$E$4:$E$7,MATCH(D28,'Bid Tiers (Popularity Score)'!$B$4:$B$7,1))) -> 1.25
A29: Move (Fitness) | B29: workout | C29: Exact | D29: 38 | E29: =IF(D29="","No Data",INDEX('Bid Tiers (Popularity Score)'!$A$4:$A$7,MATCH(D29,'Bid Tiers (Popularity Score)'!$B$4:$B$7,1))) -> Tier B — Mid Volume | F29: =IF(D29="",0.25,INDEX('Bid Tiers (Popularity Score)'!$E$4:$E$7,MATCH(D29,'Bid Tiers (Popularity Score)'!$B$4:$B$7,1))) -> 1.25
A30: Move (Fitness) | B30: gym | C30: Exact | D30: 34 | E30: =IF(D30="","No Data",INDEX('Bid Tiers (Popularity Score)'!$A$4:$A$7,MATCH(D30,'Bid Tiers (Popularity Score)'!$B$4:$B$7,1))) -> Tier B — Mid Volume | F30: =IF(D30="",0.25,INDEX('Bid Tiers (Popularity Score)'!$E$4:$E$7,MATCH(D30,'Bid Tiers (Popularity Score)'!$B$4:$B$7,1))) -> 1.25
A31: Move (Fitness) | B31: run | C31: Exact | D31: 33 | E31: =IF(D31="","No Data",INDEX('Bid Tiers (Popularity Score)'!$A$4:$A$7,MATCH(D31,'Bid Tiers (Popularity Score)'!$B$4:$B$7,1))) -> Tier B — Mid Volume | F31: =IF(D31="",0.25,INDEX('Bid Tiers (Popularity Score)'!$E$4:$E$7,MATCH(D31,'Bid Tiers (Popularity Score)'!$B$4:$B$7,1))) -> 1.25
A32: Move (Fitness) | B32: training | C32: Exact | D32: 44 | E32: =IF(D32="","No Data",INDEX('Bid Tiers (Popularity Score)'!$A$4:$A$7,MATCH(D32,'Bid Tiers (Popularity Score)'!$B$4:$B$7,1))) -> Tier B — Mid Volume | F32: =IF(D32="",0.25,INDEX('Bid Tiers (Popularity Score)'!$E$4:$E$7,MATCH(D32,'Bid Tiers (Popularity Score)'!$B$4:$B$7,1))) -> 1.25
A33: Move (Fitness) | B33: laufen | C33: Exact | D33: 5 | E33: =IF(D33="","No Data",INDEX('Bid Tiers (Popularity Score)'!$A$4:$A$7,MATCH(D33,'Bid Tiers (Popularity Score)'!$B$4:$B$7,1))) -> Tier D — Below Threshold (<5) | F33: =IF(D33="",0.25,INDEX('Bid Tiers (Popularity Score)'!$E$4:$E$7,MATCH(D33,'Bid Tiers (Popularity Score)'!$B$4:$B$7,1))) -> 0.5
A34: Move (Fitness) | B34: step counter | C34: Exact | D34: 10 | E34: =IF(D34="","No Data",INDEX('Bid Tiers (Popularity Score)'!$A$4:$A$7,MATCH(D34,'Bid Tiers (Popularity Score)'!$B$4:$B$7,1))) -> Tier C — Long-Tail | F34: =IF(D34="",0.25,INDEX('Bid Tiers (Popularity Score)'!$E$4:$E$7,MATCH(D34,'Bid Tiers (Popularity Score)'!$B$4:$B$7,1))) -> 0.75
A35: Move (Fitness) | B35: Wochenplaner | C35: Exact | D35: 11 | E35: =IF(D35="","No Data",INDEX('Bid Tiers (Popularity Score)'!$A$4:$A$7,MATCH(D35,'Bid Tiers (Popularity Score)'!$B$4:$B$7,1))) -> Tier C — Long-Tail | F35: =IF(D35="",0.25,INDEX('Bid Tiers (Popularity Score)'!$E$4:$E$7,MATCH(D35,'Bid Tiers (Popularity Score)'!$B$4:$B$7,1))) -> 0.75
A36: Move (Fitness) | B36: trainingsplan erstellen | C36: Exact | D36: 14 | E36: =IF(D36="","No Data",INDEX('Bid Tiers (Popularity Score)'!$A$4:$A$7,MATCH(D36,'Bid Tiers (Popularity Score)'!$B$4:$B$7,1))) -> Tier C — Long-Tail | F36: =IF(D36="",0.25,INDEX('Bid Tiers (Popularity Score)'!$E$4:$E$7,MATCH(D36,'Bid Tiers (Popularity Score)'!$B$4:$B$7,1))) -> 0.75
A37: Move (Fitness) | B37: workout timer | C37: Exact | D37: 5 | E37: =IF(D37="","No Data",INDEX('Bid Tiers (Popularity Score)'!$A$4:$A$7,MATCH(D37,'Bid Tiers (Popularity Score)'!$B$4:$B$7,1))) -> Tier D — Below Threshold (<5) | F37: =IF(D37="",0.25,INDEX('Bid Tiers (Popularity Score)'!$E$4:$E$7,MATCH(D37,'Bid Tiers (Popularity Score)'!$B$4:$B$7,1))) -> 0.5
A38: Move (Fitness) | B38: muskeln | C38: Exact | D38: 5 | E38: =IF(D38="","No Data",INDEX('Bid Tiers (Popularity Score)'!$A$4:$A$7,MATCH(D38,'Bid Tiers (Popularity Score)'!$B$4:$B$7,1))) -> Tier D — Below Threshold (<5) | F38: =IF(D38="",0.25,INDEX('Bid Tiers (Popularity Score)'!$E$4:$E$7,MATCH(D38,'Bid Tiers (Popularity Score)'!$B$4:$B$7,1))) -> 0.5
A39: Move (Fitness) | B39: Ausbildung | C39: Exact | D39: 5 | E39: =IF(D39="","No Data",INDEX('Bid Tiers (Popularity Score)'!$A$4:$A$7,MATCH(D39,'Bid Tiers (Popularity Score)'!$B$4:$B$7,1))) -> Tier D — Below Threshold (<5) | F39: =IF(D39="",0.25,INDEX('Bid Tiers (Popularity Score)'!$E$4:$E$7,MATCH(D39,'Bid Tiers (Popularity Score)'!$B$4:$B$7,1))) -> 0.5 | G39: German for 'training/apprenticeship' — likely a mistranslation or loose ASO-tool match for 'training', kept as-is from your export.
A40: Move (Fitness) | B40: exercises | C40: Exact | D40: 5 | E40: =IF(D40="","No Data",INDEX('Bid Tiers (Popularity Score)'!$A$4:$A$7,MATCH(D40,'Bid Tiers (Popularity Score)'!$B$4:$B$7,1))) -> Tier D — Below Threshold (<5) | F40: =IF(D40="",0.25,INDEX('Bid Tiers (Popularity Score)'!$E$4:$E$7,MATCH(D40,'Bid Tiers (Popularity Score)'!$B$4:$B$7,1))) -> 0.5
...

Sheet Belgium
A1: Bluom — Apple Search Ads — Belgium
A2: Ranked by Apple's 0-100 popularity score (same method as USA/UK/Canada).
A3: Ad Group | B3: Keyword | C3: Match Type | D3: Popularity Score | E3: Tier | F3: Suggested Max CPT ($) | G3: Notes
A4: Brand | B4: bluom | C4: Exact | D4: — | E4: Brand | F4: 0.3 | G4: Defensive brand term.
A5: Brand | B5: bluom app | C5: Exact | D5: — | E5: Brand | F5: 0.3 | G5: Defensive brand term.
A6: Brand | B6: bluom health os | C6: Exact | D6: — | E6: Brand | F6: 0.3 | G6: Defensive brand term — matches your new positioning line.
A7: Discovery | B7: [Search Match ON — no explicit keywords] | C7: Search Match | D7: — | E7: — | F7: 0.4 | G7: Especially useful here — let Apple surface real local search terms this thinner keyword list might be missing.
A8: AI Coach & Scanner | B8: coaching | C8: Exact | E8: =IF(D8="","No Data",INDEX('Bid Tiers (Popularity Score)'!$A$4:$A$7,MATCH(D8,'Bid Tiers (Popularity Score)'!$B$4:$B$7,1))) -> No Data | F8: =IF(D8="",0.25,INDEX('Bid Tiers (Popularity Score)'!$E$4:$E$7,MATCH(D8,'Bid Tiers (Popularity Score)'!$B$4:$B$7,1))) -> 0.25
A9: AI Coach & Scanner | B9: coach | C9: Exact | E9: =IF(D9="","No Data",INDEX('Bid Tiers (Popularity Score)'!$A$4:$A$7,MATCH(D9,'Bid Tiers (Popularity Score)'!$B$4:$B$7,1))) -> No Data | F9: =IF(D9="",0.25,INDEX('Bid Tiers (Popularity Score)'!$E$4:$E$7,MATCH(D9,'Bid Tiers (Popularity Score)'!$B$4:$B$7,1))) -> 0.25
A10: Fuel (Nutrition) | B10: dieet gratis | C10: Exact | E10: =IF(D10="","No Data",INDEX('Bid Tiers (Popularity Score)'!$A$4:$A$7,MATCH(D10,'Bid Tiers (Popularity Score)'!$B$4:$B$7,1))) -> No Data | F10: =IF(D10="",0.25,INDEX('Bid Tiers (Popularity Score)'!$E$4:$E$7,MATCH(D10,'Bid Tiers (Popularity Score)'!$B$4:$B$7,1))) -> 0.25
A11: Fuel (Nutrition) | B11: eten | C11: Exact | E11: =IF(D11="","No Data",INDEX('Bid Tiers (Popularity Score)'!$A$4:$A$7,MATCH(D11,'Bid Tiers (Popularity Score)'!$B$4:$B$7,1))) -> No Data | F11: =IF(D11="",0.25,INDEX('Bid Tiers (Popularity Score)'!$E$4:$E$7,MATCH(D11,'Bid Tiers (Popularity Score)'!$B$4:$B$7,1))) -> 0.25
A12: Fuel (Nutrition) | B12: calories | C12: Exact | E12: =IF(D12="","No Data",INDEX('Bid Tiers (Popularity Score)'!$A$4:$A$7,MATCH(D12,'Bid Tiers (Popularity Score)'!$B$4:$B$7,1))) -> No Data | F12: =IF(D12="",0.25,INDEX('Bid Tiers (Popularity Score)'!$E$4:$E$7,MATCH(D12,'Bid Tiers (Popularity Score)'!$B$4:$B$7,1))) -> 0.25
A13: Fuel (Nutrition) | B13: diet | C13: Exact | E13: =IF(D13="","No Data",INDEX('Bid Tiers (Popularity Score)'!$A$4:$A$7,MATCH(D13,'Bid Tiers (Popularity Score)'!$B$4:$B$7,1))) -> No Data | F13: =IF(D13="",0.25,INDEX('Bid Tiers (Popularity Score)'!$E$4:$E$7,MATCH(D13,'Bid Tiers (Popularity Score)'!$B$4:$B$7,1))) -> 0.25
A14: Fuel (Nutrition) | B14: dieet | C14: Exact | E14: =IF(D14="","No Data",INDEX('Bid Tiers (Popularity Score)'!$A$4:$A$7,MATCH(D14,'Bid Tiers (Popularity Score)'!$B$4:$B$7,1))) -> No Data | F14: =IF(D14="",0.25,INDEX('Bid Tiers (Popularity Score)'!$E$4:$E$7,MATCH(D14,'Bid Tiers (Popularity Score)'!$B$4:$B$7,1))) -> 0.25
A15: Fuel (Nutrition) | B15: macro | C15: Exact | E15: =IF(D15="","No Data",INDEX('Bid Tiers (Popularity Score)'!$A$4:$A$7,MATCH(D15,'Bid Tiers (Popularity Score)'!$B$4:$B$7,1))) -> No Data | F15: =IF(D15="",0.25,INDEX('Bid Tiers (Popularity Score)'!$E$4:$E$7,MATCH(D15,'Bid Tiers (Popularity Score)'!$B$4:$B$7,1))) -> 0.25
A16: Fuel (Nutrition) | B16: calorieënteller | C16: Exact | E16: =IF(D16="","No Data",INDEX('Bid Tiers (Popularity Score)'!$A$4:$A$7,MATCH(D16,'Bid Tiers (Popularity Score)'!$B$4:$B$7,1))) -> No Data | F16: =IF(D16="",0.25,INDEX('Bid Tiers (Popularity Score)'!$E$4:$E$7,MATCH(D16,'Bid Tiers (Popularity Score)'!$B$4:$B$7,1))) -> 0.25
A17: Fuel (Nutrition) | B17: calculateur | C17: Exact | E17: =IF(D17="","No Data",INDEX('Bid Tiers (Popularity Score)'!$A$4:$A$7,MATCH(D17,'Bid Tiers (Popularity Score)'!$B$4:$B$7,1))) -> No Data | F17: =IF(D17="",0.25,INDEX('Bid Tiers (Popularity Score)'!$E$4:$E$7,MATCH(D17,'Bid Tiers (Popularity Score)'!$B$4:$B$7,1))) -> 0.25
A18: Fuel (Nutrition) | B18: compteur de calories | C18: Exact | E18: =IF(D18="","No Data",INDEX('Bid Tiers (Popularity Score)'!$A$4:$A$7,MATCH(D18,'Bid Tiers (Popularity Score)'!$B$4:$B$7,1))) -> No Data | F18: =IF(D18="",0.25,INDEX('Bid Tiers (Popularity Score)'!$E$4:$E$7,MATCH(D18,'Bid Tiers (Popularity Score)'!$B$4:$B$7,1))) -> 0.25
A19: Fuel (Nutrition) | B19: voeding | C19: Exact | E19: =IF(D19="","No Data",INDEX('Bid Tiers (Popularity Score)'!$A$4:$A$7,MATCH(D19,'Bid Tiers (Popularity Score)'!$B$4:$B$7,1))) -> No Data | F19: =IF(D19="",0.25,INDEX('Bid Tiers (Popularity Score)'!$E$4:$E$7,MATCH(D19,'Bid Tiers (Popularity Score)'!$B$4:$B$7,1))) -> 0.25
... A23: Fuel (Nutrition) | B23: nutrition | C23: Exact | E23: =IF(D23="","No Data",INDEX('Bid Tiers (Popularity Score)'!$A$4:$A$7,MATCH(D23,'Bid Tiers (Popularity Score)'!$B$4:$B$7,1))) -> No Data | F23: =IF(D23="",0.25,INDEX('Bid Tiers (Popularity Score)'!$E$4:$E$7,MATCH(D23,'Bid Tiers (Popularity Score)'!$B$4:$B$7,1))) -> 0.25
A24: Fuel (Nutrition) | B24: calorie et régime | C24: Exact | D24: 0 | E24: =IF(D24="","No Data",INDEX('Bid Tiers (Popularity Score)'!$A$4:$A$7,MATCH(D24,'Bid Tiers (Popularity Score)'!$B$4:$B$7,1))) -> Tier D — Below Threshold (<5) | F24: =IF(D24="",0.25,INDEX('Bid Tiers (Popularity Score)'!$E$4:$E$7,MATCH(D24,'Bid Tiers (Popularity Score)'!$B$4:$B$7,1))) -> 0.5
A25: Fuel (Nutrition) | B25: compte calories | C25: Exact | E25: =IF(D25="","No Data",INDEX('Bid Tiers (Popularity Score)'!$A$4:$A$7,MATCH(D25,'Bid Tiers (Popularity Score)'!$B$4:$B$7,1))) -> No Data | F25: =IF(D25="",0.25,INDEX('Bid Tiers (Popularity Score)'!$E$4:$E$7,MATCH(D25,'Bid Tiers (Popularity Score)'!$B$4:$B$7,1))) -> 0.25
A26: Fuel (Nutrition) | B26: compte-calories | C26: Exact | E26: =IF(D26="","No Data",INDEX('Bid Tiers (Popularity Score)'!$A$4:$A$7,MATCH(D26,'Bid Tiers (Popularity Score)'!$B$4:$B$7,1))) -> No Data | F26: =IF(D26="",0.25,INDEX('Bid Tiers (Popularity Score)'!$E$4:$E$7,MATCH(D26,'Bid Tiers (Popularity Score)'!$B$4:$B$7,1))) -> 0.25
A27: Move (Fitness) | B27: sport | C27: Exact | E27: =IF(D27="","No Data",INDEX('Bid Tiers (Popularity Score)'!$A$4:$A$7,MATCH(D27,'Bid Tiers (Popularity Score)'!$B$4:$B$7,1))) -> No Data | F27: =IF(D27="",0.25,INDEX('Bid Tiers (Popularity Score)'!$E$4:$E$7,MATCH(D27,'Bid Tiers (Popularity Score)'!$B$4:$B$7,1))) -> 0.25
A28: Move (Fitness) | B28: courir | C28: Exact | E28: =IF(D28="","No Data",INDEX('Bid Tiers (Popularity Score)'!$A$4:$A$7,MATCH(D28,'Bid Tiers (Popularity Score)'!$B$4:$B$7,1))) -> No Data | F28: =IF(D28="",0.25,INDEX('Bid Tiers (Popularity Score)'!$E$4:$E$7,MATCH(D28,'Bid Tiers (Popularity Score)'!$B$4:$B$7,1))) -> 0.25
A29: Move (Fitness) | B29: run | C29: Exact | E29: =IF(D29="","No Data",INDEX('Bid Tiers (Popularity Score)'!$A$4:$A$7,MATCH(D29,'Bid Tiers (Popularity Score)'!$B$4:$B$7,1))) -> No Data | F29: =IF(D29="",0.25,INDEX('Bid Tiers (Popularity Score)'!$E$4:$E$7,MATCH(D29,'Bid Tiers (Popularity Score)'!$B$4:$B$7,1))) -> 0.25
A30: Move (Fitness) | B30: workout | C30: Exact | E30: =IF(D30="","No Data",INDEX('Bid Tiers (Popularity Score)'!$A$4:$A$7,MATCH(D30,'Bid Tiers (Popularity Score)'!$B$4:$B$7,1))) -> No Data | F30: =IF(D30="",0.25,INDEX('Bid Tiers (Popularity Score)'!$E$4:$E$7,MATCH(D30,'Bid Tiers (Popularity Score)'!$B$4:$B$7,1))) -> 0.25
A31: Move (Fitness) | B31: gym | C31: Exact | E31: =IF(D31="","No Data",INDEX('Bid Tiers (Popularity Score)'!$A$4:$A$7,MATCH(D31,'Bid Tiers (Popularity Score)'!$B$4:$B$7,1))) -> No Data | F31: =IF(D31="",0.25,INDEX('Bid Tiers (Popularity Score)'!$E$4:$E$7,MATCH(D31,'Bid Tiers (Popularity Score)'!$B$4:$B$7,1))) -> 0.25
