Workbook

Sheet Read Me
A1: What is CAC, and how to use this workbook
A3: CAC stands for Customer Acquisition Cost — the average amount you spend to turn a stranger into a paying subscriber. If you spend $1,000 on ads this month and it results in 20 people starting a paid subscription, your CAC is $50 per subscriber. Everyone who works in app growth uses this number, so it's worth having even a rough one.
A5: CAC only tells you half the story. The other half is LTV — Lifetime Value — how much net revenue one subscriber is worth to you over the whole time they stay subscribed, after Apple/Google take their cut and after Trybe takes its commission. The relationship between the two is what tells you whether the business works: if LTV is bigger than CAC, every subscriber you acquire is profitable over time. If CAC is bigger than LTV, you're paying more to acquire someone than they will ever bring in, and growth just burns cash. A common rule of thumb is that a healthy LTV:CAC ratio is 3:1 or better.
A7: For your situation specifically, 'CAC' isn't just ad spend. Every paying subscriber you get through a Trybe creator costs you three things at once: the Meta/TikTok ad spend to distribute that creator's content, the 12% commission Trybe pays the creator, and the cut Apple/Google take off every purchase (15% under their small-business program, 30% above ~$1M/year revenue). This workbook adds all three together into a 'fully-loaded cost per subscriber', not just the ad-spend-only textbook CAC, because that's the number that tells you if a creator partnership is actually worth it.
A9: Two things are still open questions with Trybe support (asked 20 Sept 2026 in their chat, 24-hour reply window quoted, no answer yet): (1) whether the 12% commission is charged once on a subscriber's first payment, or on every renewal payment for as long as they stay subscribed (i.e. on full LTV), and (2) whether Trybe charges Bluom any separate platform/subscription fee on top of that commission. Because this materially changes the real cost, the 'CAC Model' tab below models BOTH possibilities side by side as Scenario A and Scenario B, so you can see the cost either way and just re-check once Trybe replies.
A11: How to use it: open the 'Assumptions' tab. Every yellow cell with blue text is something you can and should edit — subscription price, trial conversion rate, subscriber lifetime, ad spend, and so on. Most of these are placeholders right now (flagged in the notes column) because this repo has no hardcoded price — it lives in App Store Connect / Play Console — and because you don't have live ad or retention data yet. As real numbers come in, update the yellow cells and everything on the 'CAC Model' tab recalculates automatically.
A13: My own take: don't wait for perfect numbers before running a small test. Get one creator's content live with a modest ad budget (a few hundred dollars), then plug the real trial-starts and conversions you actually see into this sheet — that will tell you more about your real CAC in a week than guessing further ever will. The one number I'd chase hardest right now is trial-to-paid conversion rate, since it swings the fully-loaded cost per subscriber more than anything else in here.
A16: Legend
A17: Editable input — change this
A18: Confirmed fact (verified directly in Trybe)
A19: Unresolved — pending Trybe support's answer
A20: Calculated automatically — don't overwrite
A22: Update, 22 Sept 2026: added Step 5/6 to the 'CAC Model' tab. Trybe still hasn't answered the two questions above, but you're now working on the assumption the 12% commission applies to every recurring payment (not just the first), and that Trybe likely also takes a small platform cut on top of the creator's commission (modeled at 1%, unconfirmed). Step 5 compares four candidate commission rates — 7%, 10%, 12% (current), 15% — on a per-subscriber basis; Step 6 shows the same four rates as real monthly company profit once Clerk, Convex and RevenueCat's own fees are folded in. Both live on the 'Assumptions' tab rows 25-38 and the 'CAC Model' tab from row 31 down.

Sheet Assumptions
A1: Bluom — CAC Model Assumptions
A2: Edit the yellow cells. Everything else recalculates on the 'CAC Model' tab.
A4: PRICING
A5: Monthly subscription price ($) | B5: 12.99 | C5: CONFIRMED, 22 Sept 2026 (Jorge) — real Bluom Pro price, replacing the earlier $9.99 placeholder. Same price quoted to creators/Trybe partners regardless of platform.
A6: Annual subscription price ($) | B6: 69.99 | C6: CONFIRMED, 22 Sept 2026 (Jorge) — real Bluom Pro annual price, replacing the earlier $59.99 placeholder. Same price quoted to creators/Trybe partners regardless of platform.
A7: Share of new paying subs on monthly plan | B7: 0.7 | C7: PLACEHOLDER — estimate until you have real plan-mix data from RevenueCat.
A8: Share of new paying subs on annual plan | B8: =1-B7 -> 0.3 | C8: Auto — always 1 minus the monthly share above.
A10: RETENTION
A11: Avg. subscriber lifetime before churn (months) | B11: 4 | C11: PLACEHOLDER — no cohort/churn data yet. Health & wellness subscription apps typically run ~10-20% monthly churn (~5-10 month avg lifetime); 4 months is a conservative early-stage guess.
A12: Free trial length (days) | B12: 7 | C12: Reference only — not used in the cost formulas below, shown for context.
A13: Trial-to-paid conversion rate | B13: 0.3 | C13: PLACEHOLDER — typical range for health/wellness apps is roughly 20-40%. This is the single biggest lever on your real cost per subscriber — replace as soon as you have live numbers.
A15: PLATFORM & CREATOR FEES
A16: Apple / Google store fee | B16: 0.15 | C16: Small Business Program rate (apps under ~$1M/year store revenue). Standard rate is 30% above that threshold — change this if/when Bluom crosses it.
A17: Trybe creator commission rate | B17: 0.12 | C17: CONFIRMED — set directly in Trybe's Commission Rules (% of GMV, media type 'Both', no per-submission cap, weekly payout, Meta attribution).
A18: Trybe commission basis (1 = first payment only, 2 = every payment incl. renewals) | B18: 2 | C18: STILL UNCONFIRMED by Trybe support (asked 20 Sept 2026, no reply yet) — but as of 22 Sept 2026 you're now modeling on the assumption it's charged on every recurring payment (full LTV), not just the first one. The 'CAC Model' tab still shows both Scenario A (first payment only) and Scenario B (recurring) side by side in Step 3/4 so you can compare either way; Step 5/6 below that use the recurring assumption throughout, since that's your working view now.
A19: Trybe platform/subscription fee ($/month) | B19: 0 | C19: UNCONFIRMED — same question sent to Trybe support 20 Sept 2026, awaiting reply. Set to 0 for now; update once confirmed (this is a flat monthly overhead, not per-subscriber, so it isn't yet folded into the per-subscriber cost below).
A21: ACQUISITION / AD SPEND
A22: Monthly Meta + TikTok ad spend distributing creator content ($) | B22: 1000 | C22: PLACEHOLDER — put in your real planned or actual monthly boost/ad budget for this content.
A23: New paying subscribers generated per month from that spend | B23: 20 | C23: PLACEHOLDER — the biggest unknown in this whole model. Once campaigns run, replace with real trial-starts x conversion-rate, or the direct number from Meta Ads Manager / RevenueCat.
A25: CREATOR COMMISSION RATE OPTIONS (for the sensitivity table on the CAC Model tab)
A26: Option 1 — lowest (e.g. Cal AI-style rate you've seen) | B26: 0.07 | C26: EDITABLE — from your own market scan of competitor apps; Cal AI reportedly runs affiliate/creator commission around here.
A27: Option 2 — rate you're now leaning toward | B27: 0.1 | C27: EDITABLE — most apps you've seen cluster around 10%; this is the rate you're considering moving to.
A28: Option 3 — current confirmed Trybe rate (same as above) | B28: =B17 -> 0.12 | C28: Auto — always mirrors the confirmed Trybe creator commission rate set above, so the two stay in sync.
A29: Option 4 — high end (ecom-style, above what you'd offer) | B29: 0.15 | C29: EDITABLE — 15%+ is typically an ecommerce/physical-product rate per your own research; SaaS margins are thinner, so this is shown as the ceiling, not a real candidate.
A31: TRYBE PLATFORM FEE (separate from the creator's own commission)
A32: Trybe platform fee, % of GMV (on top of creator commission) | B32: 0.01 | C32: UNCONFIRMED — same open question sent to Trybe support 20 Sept 2026, still awaiting reply. You're assuming ~1% as a working placeholder so the model isn't blocked on their answer; replace the moment they confirm.
A34: SAAS INFRASTRUCTURE (flat/usage overhead, not per-subscriber)
A35: Clerk (auth) — monthly cost ($) | B35: 0 | C35: CONFIRMED (Clerk's public pricing, checked 22 Sept 2026) — first 50,000 Monthly Retained Users are free on every application. Bluom is nowhere near that yet, so $0. Their Pro plan starts at $20/mo once you outgrow the free tier or need MFA/device tracking/multi-session features — update this if you upgrade. Source: clerk.com/pricing.
A36: Convex (backend) — monthly base cost ($) | B36: 25 | C36: PLACEHOLDER (Convex's public pricing, checked 22 Sept 2026) — Free plan is $0/mo with generous limits (25M function calls, 50GB storage/mo) but Convex says it may throttle/error if you stay over for long. The Professional/Starter Plus plan is $25/mo per developer and guarantees your app keeps serving traffic under load, plus metered overage. Set to $0 if you're confident you're still comfortably inside the free limits. Source: convex.dev/pricing.
A37: RevenueCat fee rate above its free threshold | B37: 0.01 | C37: CONFIRMED (RevenueCat's public pricing, checked 22 Sept 2026) — free until $2,500/mo Monthly Tracked Revenue (MTR), then 1% of MTR above that threshold, no fixed monthly minimum. Source: revenuecat.com/pricing.
A38: RevenueCat free threshold ($ MTR/month) | B38: 2500 | C38: CONFIRMED — see note above.

Sheet CAC Model
A1: Bluom — CAC Model
A2: Every number below flows from the 'Assumptions' tab. CAC (the cost to acquire a subscriber) is the same in both scenarios, because Trybe is paid on the first purchase either way. The open question — first payment only vs. every renewal — only changes the ongoing cost and therefore lifetime value (LTV), so it's modeled as Scenario A / Scenario B from Step 3 onward.
A4: STEP 1 — Blended pricing
A5: Blended ARPU per subscriber per month ($) | B5: =(Assumptions!B5*Assumptions!B7)+(Assumptions!B6/12*Assumptions!B8) -> 10.84275
A6: Blended amount of a subscriber's FIRST payment ($) | B6: =(Assumptions!B5*Assumptions!B7)+(Assumptions!B6*Assumptions!B8) -> 30.09 | C6: Monthly subs pay one month up front; annual subs pay the full year up front.
A8: STEP 2 — Acquisition cost (CAC) — same in both scenarios
A9: Monthly ad spend distributing creator content ($) | B9: =Assumptions!B22 -> 1000
A10: New paying subscribers generated per month | B10: =Assumptions!B23 -> 20
A11: Ad spend per new subscriber ("marketing-only" CAC) ($) | B11: =B9/B10 -> 50
A12: Trybe commission on that first payment ($) | B12: =B6*Assumptions!B17 -> 3.6108
A13: CAC — fully-loaded cost per acquired paying subscriber ($) | B13: =B11+B12 -> 53.6108 | C13: Equals ad spend per subscriber + Trybe's cut of their first payment. This is what the Trybe support question was really asking for.
A14: Trybe platform/subscription fee, flat ($/month, not yet in CAC above) | B14: =Assumptions!B19 -> 0 | C14: UNCONFIRMED with Trybe — a flat monthly cost, not per-subscriber, so kept separate.
A16: STEP 3 — Ongoing Trybe cost & net monthly revenue (this is where the open question matters)
B17: Scenario A — commission on first payment only | C17: Scenario B — commission on every payment (full LTV)
A18: Ongoing Trybe commission after the first payment | B18: 0 | C18: =B5*Assumptions!B17 -> 1.30113
A19: Net monthly revenue to Bluom (after store fee + ongoing Trybe cut) | B19: =B5*(1-Assumptions!B16) -> 9.2163375 | C19: =B5*(1-Assumptions!B16-Assumptions!B17) -> 7.9152075
A21: STEP 4 — Lifetime value & payback
A22: LTV — net revenue over full subscriber lifetime ($) | B22: =B19*Assumptions!B11 -> 36.86535 | C22: =C19*Assumptions!B11 -> 31.66083
A23: LTV : CAC ratio (3:1 or higher is generally considered healthy) | B23: =B22/$B$13 -> 0.68764782 | C23: =C22/$B$13 -> 0.59056813
A24: Net profit per subscriber over lifetime ($) [LTV − CAC] | B24: =B22-$B$13 -> -16.74545 | C24: =C22-$B$13 -> -21.94997
A25: Payback period (months) — CAC ÷ net monthly revenue | B25: =$B$13/B19 -> 5.8169311 | C25: =$B$13/C19 -> 6.7731389
A26: Verdict | B26: =IF(B23>=3,"Healthy (3:1+)",IF(B23>=1,"Marginal (1-3:1) — works but thin","Underwater (<1:1) — losing money per subscriber")) -> Underwater (<1:1) — losing money per subscriber | C26: =IF(C23>=3,"Healthy (3:1+)",IF(C23>=1,"Marginal (1-3:1) — works but thin","Underwater (<1:1) — losing money per subscriber")) -> Underwater (<1:1) — losing money per subscriber
A28: Note on the approximation: Scenario B spreads Trybe's ongoing cut evenly across every month of the subscriber's lifetime for simplicity, including month 1 (whose first-payment commission is already counted once in CAC above) — directionally correct, slightly conservative, not exact to the penny. Good enough to compare the two scenarios; replace with exact numbers once you have real cohort billing data.
A31: STEP 5 — Per-subscriber unit economics if you change the creator commission rate
A32: Uses the recurring-commission assumption (Scenario B logic above) at four candidate rates, so you can see whether 10% (or lower) still clears a healthy LTV:CAC before you change anything with Trybe or creators.
A34: Scenario | B34: Option 1 — 7% | C34: Option 2 — 10% | D34: Option 3 — 12% (current) | E34: Option 4 — 15%
A35: Creator commission rate | B35: =Assumptions!B26 -> 0.07 | C35: =Assumptions!B27 -> 0.1 | D35: =Assumptions!B28 -> 0.12 | E35: =Assumptions!B29 -> 0.15
A36: Trybe creator commission (per subscriber per month, $) | B36: =$B$5*B35 -> 0.7589925 | C36: =$B$5*C35 -> 1.084275 | D36: =$B$5*D35 -> 1.30113 | E36: =$B$5*E35 -> 1.6264125
A37: Net monthly revenue per subscriber (after store fee + commission + Trybe platform fee) | B37: =$B$5*(1-Assumptions!$B$16-B35-Assumptions!$B$32) -> 8.3489175 | C37: =$B$5*(1-Assumptions!$B$16-C35-Assumptions!$B$32) -> 8.023635 | D37: =$B$5*(1-Assumptions!$B$16-D35-Assumptions!$B$32) -> 7.80678 | E37: =$B$5*(1-Assumptions!$B$16-E35-Assumptions!$B$32) -> 7.4814975
A38: LTV — net revenue over full subscriber lifetime ($) | B38: =B37*Assumptions!$B$11 -> 33.39567 | C38: =C37*Assumptions!$B$11 -> 32.09454 | D38: =D37*Assumptions!$B$11 -> 31.22712 | E38: =E37*Assumptions!$B$11 -> 29.92599
A39: CAC — fully-loaded cost per acquired subscriber ($) | B39: =$B$11+$B$6*B35 -> 52.1063 | C39: =$B$11+$B$6*C35 -> 53.009 | D39: =$B$11+$B$6*D35 -> 53.6108 | E39: =$B$11+$B$6*E35 -> 54.5135
A40: LTV : CAC ratio (3:1+ is healthy) | B40: =B38/B39 -> 0.64091425 | C40: =C38/C39 -> 0.60545455 | D40: =D38/D39 -> 0.58247816 | E40: =E38/E39 -> 0.54896475
A41: Net profit per subscriber over lifetime ($) [LTV − CAC] | B41: =B38-B39 -> -18.71063 | C41: =C38-C39 -> -20.91446 | D41: =D38-D39 -> -22.38368 | E41: =E38-E39 -> -24.58751
A42: Verdict | B42: =IF(B40>=3,"Healthy (3:1+)",IF(B40>=1,"Marginal (1-3:1) — works but thin","Underwater (<1:1) — losing money per subscriber")) -> Underwater (<1:1) — losing money per subscriber | C42: =IF(C40>=3,"Healthy (3:1+)",IF(C40>=1,"Marginal (1-3:1) — works but thin","Underwater (<1:1) — losing money per subscriber")) -> Underwater (<1:1) — losing money per subscriber | D42: =IF(D40>=3,"Healthy (3:1+)",IF(D40>=1,"Marginal (1-3:1) — works but thin","Underwater (<1:1) — losing money per subscriber")) -> Underwater (<1:1) — losing money per subscriber | E42: =IF(E40>=3,"Healthy (3:1+)",IF(E40>=1,"Marginal (1-3:1) — works but thin","Underwater (<1:1) — losing money per subscriber")) -> Underwater (<1:1) — losing money per subscriber
A44: STEP 6 — Company-wide monthly P&L at steady state, across the same 4 commission rates
A45: Steady state = new subscribers keep coming in at your current pace and old ones churn out at your current avg. lifetime, so the active base stops growing. This answers 'do I make money' in real dollars, not just per-subscriber ratios.
A47: Scenario | B47: Option 1 — 7% | C47: Option 2 — 10% | D47: Option 3 — 12% (current) | E47: Option 4 — 15%
A48: Steady-state active paying subscribers | B48: =Assumptions!$B$23*Assumptions!$B$11 -> 80 | C48: =Assumptions!$B$23*Assumptions!$B$11 -> 80 | D48: =Assumptions!$B$23*Assumptions!$B$11 -> 80 | E48: =Assumptions!$B$23*Assumptions!$B$11 -> 80
A49: Total monthly recurring revenue, gross ($) | B49: =B48*$B$5 -> 867.42 | C49: =C48*$B$5 -> 867.42 | D49: =D48*$B$5 -> 867.42 | E49: =E48*$B$5 -> 867.42
A50: Less: Apple / Google store fee ($) | B50: =B49*Assumptions!$B$16 -> 130.113 | C50: =C49*Assumptions!$B$16 -> 130.113 | D50: =D49*Assumptions!$B$16 -> 130.113 | E50: =E49*Assumptions!$B$16 -> 130.113
...
